Workbook

Sheet 週間スケジュール
A1: An-field様 給与計算業務 完全移管 週間進行管理（2026/9/9 ～ 10/31）
A2: 9月＝全社情報整理・優先順位決定・先行企業引継ぎ・テスト計算・採用 ／ 10月＝先行企業 実運用・対象企業拡大・運用精度確認
A3: ※本シートの件数・工数・人数はすべて【暫定計画値】です。会社別工数・実績確認後に更新してください（確定値ではありません）。
A4: 【重要】10月＝完全移管ではありません。10月は「先行企業 実運用・対象企業拡大」フェーズです。
A5: 計画（期間・フェーズ・対応内容） | D5: 暫定計画値 ／ 実績入力 ／ 自動計算 | L5: 完了条件・運用管理（手入力）
A6: 期間 | B6: フェーズ | C6: 主な対応内容 | D6: 計画対象企業数 | E6: 実績対象企業数 | F6: 実運用累計企業数 | G6: 計画工数 | H6: 実績工数 | I6: 必要人数 | J6: 実働人数 | K6: 1社あたり平均工数 | L6: 完了条件 | M6: ステータス | N6: 課題 | O6: 次週アクション
A7: 2026/9/9（水）～9/13（日） | B7: 全社情報整理・移管設計 | C7: ・100〜110社の一覧整理 ・会社別工数情報の回収 ・チェックシート回収 ・給与計算ソフト整理 ・勤怠取得方法整理 ・締日、支給日確認 ・特殊ルール確認 ・例外処理確認 ・難易度分類 ・優先順位決定 ・先行移管候補企業選定 ・追加ワーカー募集状況確認 | D7: 0 | F7: =SUMPRODUCT(('案件進捗管理'!$V$6:$V$115<>"")*('案件進捗管理'!$V$6:$V$115<=DATE(2026,9,13))) | G7: 60 | I7: =IF('キャパシティ・必要人数'!$D$29=0,"",ROUNDUP(G7/'キャパシティ・必要人数'!$D$29,0)) | K7: =IF(OR(E7="",N(E7)=0,H7=""),"",H7/E7) | L7: ・対象企業の全体像が見えている ・先行対象企業が選定されている ・会社別工数確認を開始できている 【暫定目安】100〜110社の一覧化／先行候補企業10〜15社程度を抽出（確定値ではなく暫定候補） | M7: 未着手
A8: 2026/9/14（月）～9/20（日） | B8: 先行企業引継ぎ・工数計測 | C8: ・優先企業の業務レクチャー ・勤怠取得方法確認 ・給与計算フロー確認 ・資料回収方法確認 ・顧客対応方法確認 ・納品方法確認 ・チェックシート確認 ・1社あたり実工数計測開始 ・追加ワーカー面接、選考 | D8: 6 | F8: =SUMPRODUCT(('案件進捗管理'!$V$6:$V$115<>"")*('案件進捗管理'!$V$6:$V$115<=DATE(2026,9,20))) | G8: 80 | I8: =IF('キャパシティ・必要人数'!$D$29=0,"",ROUNDUP(G8/'キャパシティ・必要人数'!$D$29,0)) | K8: =IF(OR(E8="",N(E8)=0,H8=""),"",H8/E8) | L8: ・先行企業の業務内容を担当者が把握 ・1社あたり実工数の計測を開始できている ・追加ワーカーの選考が進行している 【暫定目安】先行引継ぎ5〜8社程度／テスト計算3〜5社程度 【重要】件数よりも、実工数・難易度・必要スキル・担当可能人数の把握を優先 | M8: 未着手
A9: 2026/9/21（月）～9/27（日） | B9: テスト計算・移管モデル確立 | C9: ・先行企業テスト計算 ・計算結果確認 ・エラー記録 ・差し戻し記録 ・顧客対応テスト ・納品フロー確認 ・1社あたり工数更新 ・難易度A/B/C基準確定 ・標準企業／特殊企業分類 ・秘書チーム／ワーカー役割分担 ・必要人数再計算 | D9: 6 | F9: =SUMPRODUCT(('案件進捗管理'!$V$6:$V$115<>"")*('案件進捗管理'!$V$6:$V$115<=DATE(2026,9,27))) | G9: 90 | I9: =IF('キャパシティ・必要人数'!$D$29=0,"",ROUNDUP(G9/'キャパシティ・必要人数'!$D$29,0)) | K9: =IF(OR(E9="",N(E9)=0,H9=""),"",H9/E9) | L9: ・難易度A/B/C基準が確定している ・秘書チーム／ワーカーの役割分担が決まっている ・総必要工数÷担当者処理能力から10月の実運用可能社数を再計算できている 【暫定目安】先行引継ぎ累計10〜15社程度／テスト計算8〜12社程度 | M9: 未着手
A10: 2026/9/28（月）～10/4（日） | B10: 先行企業 実運用開始 | C10: ・テスト済み企業から実運用開始 ・資料回収 ・勤怠取得 ・給与計算 ・質問対応 ・顧客対応 ・納品 ・進捗管理 まで弊社側主体で実施 ・確認ポイント記録 ・差し戻し原因記録 ・運用課題抽出 ・追加ワーカー教育 | D10: 0 | F10: =SUMPRODUCT(('案件進捗管理'!$V$6:$V$115<>"")*('案件進捗管理'!$V$6:$V$115<=DATE(2026,10,4))) | G10: 100 | I10: =IF('キャパシティ・必要人数'!$D$29=0,"",ROUNDUP(G10/'キャパシティ・必要人数'!$D$29,0)) | K10: =IF(OR(E10="",N(E10)=0,H10=""),"",H10/E10) | L10: ・先行企業で資料回収〜納品まで弊社主体の運用が成立している ・差し戻し原因が記録されている ・追加ワーカーの教育が開始されている 【暫定目安】実運用開始5〜10社程度 ※実工数によって自動見直しする | M10: 未着手
A11: 2026/10/5（月）～10/11（日） | B11: 先行企業安定化・第2グループ移管 | C11: ・先行企業の実運用継続 ・発生課題の修正 ・チェックシート改善 ・第2グループ引継ぎ ・定型案件を追加ワーカーへ移管 ・秘書チームは高難易度案件・管理業務中心へ移行 | D11: 8 | F11: =SUMPRODUCT(('案件進捗管理'!$V$6:$V$115<>"")*('案件進捗管理'!$V$6:$V$115<=DATE(2026,10,11))) | G11: 110 | I11: =IF('キャパシティ・必要人数'!$D$29=0,"",ROUNDUP(G11/'キャパシティ・必要人数'!$D$29,0)) | K11: =IF(OR(E11="",N(E11)=0,H11=""),"",H11/E11) | L11: ・先行企業の運用課題が解消されている ・定型案件の追加ワーカー移管が開始されている ・秘書チームが高難易度案件・管理業務中心に移行できている 【暫定目安】新規引継ぎ5〜10社程度／実運用累計10〜15社程度 | M11: 未着手
A12: 2026/10/12（月）～10/18（日） | B12: 実運用対象拡大 | C12: ・実運用企業追加 ・第2グループテスト計算 ・定型企業のワーカー移管 ・特殊企業の秘書チーム対応 ・顧客対応範囲拡大 ・An-field様側の確認工数測定 ・会社別工数再計測 | D12: 6 | F12: =SUMPRODUCT(('案件進捗管理'!$V$6:$V$115<>"")*('案件進捗管理'!$V$6:$V$115<=DATE(2026,10,18))) | G12: 120 | I12: =IF('キャパシティ・必要人数'!$D$29=0,"",ROUNDUP(G12/'キャパシティ・必要人数'!$D$29,0)) | K12: =IF(OR(E12="",N(E12)=0,H12=""),"",H12/E12) | L12: ・An-field様側の確認工数が測定できている ・会社別工数が再計測され更新されている ・担当者単独で処理できた企業数が把握できている 【暫定目安】実運用累計15〜20社程度 【重要】企業数だけでなく、処理できた総工数／An-field様の確認が不要だった企業数／担当者単独で処理できた企業数もKPI化する | M12: 未着手
A13: 2026/10/19（月）～10/25（日） | B13: 移管ペース拡大・処理能力確認 | C13: ・対象企業追加 ・難易度別担当再配置 ・バックアップ担当設定 ・属人化案件抽出 ・追加採用要否判定 ・処理能力再計算 ・運用課題整理 ・標準業務フロー改善 | D13: 8 | F13: =SUMPRODUCT(('案件進捗管理'!$V$6:$V$115<>"")*('案件進捗管理'!$V$6:$V$115<=DATE(2026,10,25))) | G13: 130 | I13: =IF('キャパシティ・必要人数'!$D$29=0,"",ROUNDUP(G13/'キャパシティ・必要人数'!$D$29,0)) | K13: =IF(OR(E13="",N(E13)=0,H13=""),"",H13/E13) | L13: ・平均工数／実働人数／1人あたり処理可能工数／1人あたり処理可能社数が算出できている ・バックアップ担当が設定されている ・属人化案件が抽出され追加採用要否を判定できている 【暫定目安】実運用累計20〜30社程度 | M13: 未着手
A14: 2026/10/26（月）～10/31（土） | B14: 10月総括・次フェーズ判断 | C14: ・実運用実績集計 ・会社別平均工数算出 ・難易度別平均工数算出 ・担当者別処理能力算出 ・追加必要人数算出 ・完全移管までの残工数算出 ・課題一覧整理 ・今後の移管方針判断 | D14: 5 | F14: =SUMPRODUCT(('案件進捗管理'!$V$6:$V$115<>"")*('案件進捗管理'!$V$6:$V$115<=DATE(2026,10,31))) | G14: 110 | I14: =IF('キャパシティ・必要人数'!$D$29=0,"",ROUNDUP(G14/'キャパシティ・必要人数'!$D$29,0)) | K14: =IF(OR(E14="",N(E14)=0,H14=""),"",H14/E14) | L14: 【10月末ゴール】以下がすべて明確になっている ・実運用済み企業数／自走可能企業数／完全移管企業数 ・残企業数／残工数／必要追加人数 ・1人あたりの処理能力と今後の移管ペース 【暫定目安】実運用累計25〜35社程度 ※確定目標ではなく、現時点の暫定想定 | M14: 未着手
A15: 合計 / 最終（暫定計画値） | D15: =SUM(D7:D14) | E15: =IF(COUNT(E7:E14)=0,"",SUM(E7:E14)) | F15: =MAX(F7:F14) | G15: =SUM(G7:G14) | H15: =IF(COUNT(H7:H14)=0,"",SUM(H7:H14)) | I15: =MAX(I7:I14) | J15: =IF(COUNT(J7:J14)=0,"",MAX(J7:J14)) | K15: =IF(OR(E15="",H15=""),"",H15/E15) | L15: ※合計は暫定計画値の積み上げです。件数目標のために無理に移管せず、実工数と品質をもとに件数を調整してください。
A17: 【完全移管の定義】「給与計算ができる状態」ではありません。資料回収・顧客対応・質問対応・勤怠取得・給与計算・チェック・納品・進捗管理・担当者管理・欠員時の再配置まで、An-field様が日常的に管理しなくても回る状態を指します。
A18: 【進捗は3軸で評価】①件数進捗＝何社が各ステータスまで進んだか ②工数進捗＝全体工数のうち何時間分の業務を移管できたか ③自走進捗＝何社がAn-field様の日常的な確認なしで運用できる状態になったか。「何社移管したか」だけでは判断しないでください。
A19: 【計画の考え方】「毎週○社移管する」という件数ありきの計画にはしません。会社ごとに給与計算工数・やり取り時間・資料回収時間・質問対応時間・使用ツール・締日・支給日・例外処理・特殊ルール・難易度が異なるため、『会社別総工数 × 難易度 ÷ 担当者処理能力』で処理能力を算出し、件数は結果として決まります。
A20: 【暫定値の扱い】計画対象企業数・計画工数・必要人数は暫定計画値です。実工数が不明なものは「暫定値」「要確認」とし、実績入力後に再計算してください。必要人数は『計画工数 ÷ 1人あたり週有効稼働時間』で自動算出しています（有効稼働時間はキャパシティシートの入力値から算出）。
A21: 【凡例】白＝暫定計画値（固定） ／ 薄い黄色＝手入力 ／ 薄いグレー＝自動計算 ／ 赤＝警告・遅延・人員不足のみ。実働人数が必要人数を下回る週は実働人数セルが赤くなります。

Sheet ガントチャート
A1: An-field様 給与計算業務 完全移管 ガントチャート（2026/9/9 ～ 10/31）
A2: 色分け：情報整理＝グレー／採用＝紫／引継ぎ＝青／テスト＝水色／実運用＝緑／検証＝オレンジ／リスク＝赤
A3: ※本シートの件数・工数・人数はすべて【暫定計画値】です。会社別工数・実績確認後に更新してください（確定値ではありません）。
A4: 【重要】10月＝完全移管ではありません。10月は「先行企業 実運用・対象企業拡大」フェーズです。
A5: 【凡例】区分の色 | I5: 情報整理 | O5: 採用 | U5: 引継ぎ | AA5: テスト | AG5: 実運用 | AM5: 検証 | AS5: リスク
A6: 月フェーズ | H6: 9月：全社情報整理・優先順位決定・先行企業引継ぎ・テスト計算・採用 | AD6: 10月：先行企業 実運用・対象企業拡大・運用精度確認 ※完全移管ではありません
A7: No. | B7: タスク | C7: 区分 | D7: 開始日 （暫定） | E7: 終了日 （暫定） | F7: 日数 | G7: 進捗率 【入力】 | H7: 第1週 9/9～9/13 | M7: 第2週 9/14～9/20 | T7: 第3週 9/21～9/27 | AA7: 第4週 9/28～10/4 | AH7: 第5週 10/5～10/11 | AO7: 第6週 10/12～10/18 | AV7: 第7週 10/19～10/25 | BC7: 第8週 10/26～10/31
H8: 46274 | I8: 46275 | J8: 46276 | K8: 46277 | L8: 46278 | M8: 46279 | N8: 46280 | O8: 46281 | P8: 46282 | Q8: 46283 | R8: 46284 | S8: 46285 | T8: 46286 | U8: 46287 | V8: 46288 | W8: 46289 | X8: 46290 | Y8: 46291 | Z8: 46292 | AA8: 46293 | AB8: 46294 | AC8: 46295 | AD8: 46296 | AE8: 46297 | AF8: 46298 | AG8: 46299 | AH8: 46300 | AI8: 46301 | AJ8: 46302 | AK8: 46303 | AL8: 46304 | AM8: 46305 | AN8: 46306 | AO8: 46307 | AP8: 46308 | AQ8: 46309 | AR8: 46310 | AS8: 46311 | AT8: 46312 | AU8: 46313 | AV8: 46314 | AW8: 46315 | AX8: 46316 | AY8: 46317 | AZ8: 46318 | BA8: 46319 | BB8: 46320 | BC8: 46321 | BD8: 46322 | BE8: 46323 | BF8: 46324 | BG8: 46325 | BH8: 46326
H9: 水 | I9: 木 | J9: 金 | K9: 土 | L9: 日 | M9: 月 | N9: 火 | O9: 水 | P9: 木 | Q9: 金 | R9: 土 | S9: 日 | T9: 月 | U9: 火 | V9: 水 | W9: 木 | X9: 金 | Y9: 土 | Z9: 日 | AA9: 月 | AB9: 火 | AC9: 水 | AD9: 木 | AE9: 金 | AF9: 土 | AG9: 日 | AH9: 月 | AI9: 火 | AJ9: 水 | AK9: 木 | AL9: 金 | AM9: 土 | AN9: 日 | AO9: 月 | AP9: 火 | AQ9: 水 | AR9: 木 | AS9: 金 | AT9: 土 | AU9: 日 | AV9: 月 | AW9: 火 | AX9: 水 | AY9: 木 | AZ9: 金 | BA9: 土 | BB9: 日 | BC9: 月 | BD9: 火 | BE9: 水 | BF9: 木 | BG9: 金 | BH9: 土
A10: 1 | B10: 全社情報整理 | C10: 情報整理 | D10: 46274 | E10: 46285 | F10: =E10-D10+1 | G10: 0
A11: 2 | B11: 会社別工数確認 | C11: 情報整理 | D11: 46274 | E11: 46326 | F11: =E11-D11+1 | G11: 0
A12: 3 | B12: 難易度分類 | C12: 情報整理 | D12: 46274 | E12: 46292 | F12: =E12-D12+1 | G12: 0
A13: 4 | B13: 優先順位決定 | C13: 情報整理 | D13: 46274 | E13: 46278 | F13: =E13-D13+1 | G13: 0
A14: 5 | B14: 先行企業選定 | C14: 情報整理 | D14: 46274 | E14: 46278 | F14: =E14-D14+1 | G14: 0
A15: 6 | B15: 先行企業引継ぎ | C15: 引継ぎ | D15: 46279 | E15: 46292 | F15: =E15-D15+1 | G15: 0
A16: 7 | B16: テスト計算 | C16: テスト | D16: 46282 | E16: 46299 | F16: =E16-D16+1 | G16: 0
A17: 8 | B17: 追加ワーカー募集 | C17: 採用 | D17: 46274 | E17: 46292 | F17: =E17-D17+1 | G17: 0
A18: 9 | B18: 追加ワーカー面接 | C18: 採用 | D18: 46279 | E18: 46299 | F18: =E18-D18+1 | G18: 0
A19: 10 | B19: 追加ワーカー教育 | C19: 採用 | D19: 46293 | E19: 46320 | F19: =E19-D19+1 | G19: 0
A20: 11 | B20: 先行企業実運用 | C20: 実運用 | D20: 46293 | E20: 46326 | F20: =E20-D20+1 | G20: 0
A21: 12 | B21: 第2グループ移管 | C21: 引継ぎ | D21: 46300 | E21: 46313 | F21: =E21-D21+1 | G21: 0
... A29: 20 | B29: 採用遅延・欠員・属人化リスク監視 | C29: リスク | D29: 46274 | E29: 46326 | F29: =E29-D29+1 | G29: 0
AA30: ▲ 9/28 先行企業 実運用開始 | AZ30: ▲ 10/31 10月総括・次フェーズ判断
A32: 【9月マイルストーン】9/13：全社一覧化・先行候補選定 │ 9/20：先行引継ぎ開始・実工数計測開始 │ 9/27：難易度A/B/C基準確定・役割分担確定・必要人数再計算 │ 9/28：先行企業 実運用開始
A33: 【10月マイルストーン】10/11：先行企業安定化・第2グループ引継ぎ │ 10/18：An-field様側の確認工数測定 │ 10/25：処理能力再計算・追加採用要否判定 │ 10/31：10月総括・次フェーズ判断
A34: 【重要】10月末のゴールは「100〜110社の完全移管」ではありません。先行企業で実運用が成立し、企業別工数・難易度・役割分担・1人あたり処理能力・残工数・追加必要人数が数値で把握できている状態がゴールです。
A35: 【凡例】色付きバー＝暫定計画期間 ／ 薄い黄色＝手入力（進捗率） ／ グレーの列＝土日 ／ 金色の縦線＝9/28 実運用開始・10/31 総括

Sheet 案件進捗管理
A1: 案件進捗管理（対象 100〜110社） An-field様 給与計算業務 完全移管
A2: 【完全移管の定義】資料回収・給与計算・不明点対応・顧問先とのやり取り・納品・担当者管理まで、An-field様の日常的な管理なしで完結する状態。 ※10月＝完全移管ではありません（10月は先行企業 実運用・対象企業拡大）。
A3: ※工数は1社あたり【月間】の想定時間（h）。現時点で実工数が不明なものは空欄のまま「要確認」とし、実績入力後に再計算してください（暫定値）。企業名は仮名称です。対象が100社の場合は不要行を削除してください。
A4: No. | B4: 企業名 | C4: 優先順位 | D4: 難易度 | E4: 移管ステータス | F4: 秘書／ワーカー区分 | G4: 主担当 | H4: バックアップ担当 | I4: 給与計算ソフト | J4: 勤怠ツール | K4: 締日 | L4: 支給日 | M4: 給与計算工数 | N4: 資料回収工数 | O4: 顧客対応工数 | P4: 質問対応工数 | Q4: 合計工数 | R4: チェックシート受領 | S4: 業務レクチャー完了 | T4: 初回計算完了 | U4: 検証完了 | V4: 実運用開始日 | W4: 自走可能日 | X4: 完全移管日 | Y4: 課題 | Z4: 備考
A5: 例 | B5: （記入例）株式会社サンプル | C5: 1：最優先 | D5: B：中程度 | E5: 2. 引継ぎ中 | F5: 秘書チーム中心 | G5: 山田 | H5: 佐藤 | I5: セルズ給与 | J5: KING OF TIME | K5: 末日 | L5: 翌月15日 | M5: 4 | N5: 1.5 | O5: 1 | P5: 0.5 | Q5: =SUM(M5:P5) | R5: TRUE | S5: TRUE | T5: FALSE | U5: FALSE | Y5: 賞与月の計算ルールが未確認 | Z5: 従業員32名／例外：時給者の深夜割増あり
A6: 1 | B6: 企業001 | E6: 1. 未着手 | Q6: =SUM(M6:P6) | R6: FALSE | S6: FALSE | T6: FALSE | U6: FALSE
A7: 2 | B7: 企業002 | E7: 1. 未着手 | Q7: =SUM(M7:P7) | R7: FALSE | S7: FALSE | T7: FALSE | U7: FALSE
A8: 3 | B8: 企業003 | E8: 1. 未着手 | Q8: =SUM(M8:P8) | R8: FALSE | S8: FALSE | T8: FALSE | U8: FALSE
A9: 4 | B9: 企業004 | E9: 1. 未着手 | Q9: =SUM(M9:P9) | R9: FALSE | S9: FALSE | T9: FALSE | U9: FALSE
A10: 5 | B10: 企業005 | E10: 1. 未着手 | Q10: =SUM(M10:P10) | R10: FALSE | S10: FALSE | T10: FALSE | U10: FALSE
A11: 6 | B11: 企業006 | E11: 1. 未着手 | Q11: =SUM(M11:P11) | R11: FALSE | S11: FALSE | T11: FALSE | U11: FALSE
A12: 7 | B12: 企業007 | E12: 1. 未着手 | Q12: =SUM(M12:P12) | R12: FALSE | S12: FALSE | T12: FALSE | U12: FALSE
A13: 8 | B13: 企業008 | E13: 1. 未着手 | Q13: =SUM(M13:P13) | R13: FALSE | S13: FALSE | T13: FALSE | U13: FALSE
A14: 9 | B14: 企業009 | E14: 1. 未着手 | Q14: =SUM(M14:P14) | R14: FALSE | S14: FALSE | T14: FALSE | U14: FALSE
A15: 10 | B15: 企業010 | E15: 1. 未着手 | Q15: =SUM(M15:P15) | R15: FALSE | S15: FALSE | T15: FALSE | U15: FALSE
A16: 11 | B16: 企業011 | E16: 1. 未着手 | Q16: =SUM(M16:P16) | R16: FALSE | S16: FALSE | T16: FALSE | U16: FALSE
A17: 12 | B17: 企業012 | E17: 1. 未着手 | Q17: =SUM(M17:P17) | R17: FALSE | S17: FALSE | T17: FALSE | U17: FALSE
... A115: 110 | B115: 企業110 | E115: 1. 未着手 | Q115: =SUM(M115:P115) | R115: FALSE | S115: FALSE | T115: FALSE | U115: FALSE

Sheet キャパシティ・必要人数
A1: キャパシティ・必要人数 試算（An-field様 給与計算業務 完全移管）
A2: 算出ロジック：会社別総工数 × 難易度 ÷ 担当者処理能力 → 必要人数・週あたり処理可能社数・月あたり移管可能件数
A3: ※本シートの件数・工数・人数はすべて【暫定計画値】です。会社別工数・実績確認後に更新してください（確定値ではありません）。
A4: 【重要】10月＝完全移管ではありません。10月は「先行企業 実運用・対象企業拡大」フェーズです。
A6: ① 入力項目（薄い黄色セルを入力 ／ すべて暫定値・要確認・実績入力後に再計算）
B7: 項目 | D7: 値 | E7: 単位 | F7: 説明・根拠
B8: 対象企業総数 | E8: 社 | F8: 【入力・空欄可】空欄の場合は案件進捗管理シートの企業名から自動集計します
B9: 会社別総工数（月・合計） | E9: h/月 | F9: 【入力・空欄可】空欄の場合は案件進捗管理シートの合計工数から自動集計します
B10: 秘書チーム人数 | D10: 3 | E10: 名 | F10: 全体管理・顧客対応・資料回収・質問対応・高難易度計算・教育・品質管理・納品管理・欠員時の再配置
B11: 追加ワーカー人数 | D11: 2 | E11: 名 | F11: 定型給与計算・チェックシートで自走可能な企業・手順が確立した業務
B12: 1人あたり週稼働可能時間 | D12: 30 | E12: h/週 | F12: 【暫定値・要確認】採用条件確定後に更新
B13: 管理業務比率 | D13: 0.2 | E13: ％ | F13: 【暫定値】打合せ・報告・調整など、直接作業以外に充てる割合
B14: 教育工数（週・チーム全体） | D14: 10 | E14: h/週 | F14: 【暫定値】追加ワーカー教育。処理可能工数から差し引く
B15: 品質確認工数（週・チーム全体） | D15: 8 | E15: h/週 | F15: 【暫定値】秘書チームによるチェック。処理可能工数から差し引く
B16: 移管1社あたり追加工数 | D16: 6 | E16: h/社 | F16: 【暫定値】引継ぎ・レクチャー・テスト計算・検証にかかる初期工数。月あたり移管可能件数の算定に使用
B17: 難易度係数 A：標準 | D17: 1 | E17: 倍 | F17: 【暫定値】9/27までに基準確定。実績入力後に再計算
B18: 難易度係数 B：中程度 | D18: 1.3 | E18: 倍 | F18: 【暫定値】難易度未判定の企業にもこの係数を適用
B19: 難易度係数 C：複雑 | D19: 1.7 | E19: 倍 | F19: 【暫定値】特殊ルール・例外処理が多い企業
B20: 月換算係数（週→月） | D20: 4.33 | E20: 週/月 | F20: 1ヶ月＝約4.33週
A22: ② 自動計算（グレーのセル ／ 入力値と案件進捗管理シートから算出）
B23: 項目 | D23: 値 | E23: 単位 | F23: 計算式・考え方
B24: 対象企業総数（採用値） | D24: =IF('キャパシティ・必要人数'!$D$8="",COUNTA('案件進捗管理'!$B$6:$B$115),'キャパシティ・必要人数'!$D$8) | E24: 社 | F24: 入力欄が空欄なら案件進捗管理シートから自動集計
B25: 会社別総工数（採用値・月） | D25: =IF('キャパシティ・必要人数'!$D$9="",SUM('案件進捗管理'!$Q$6:$Q$115),'キャパシティ・必要人数'!$D$9) | E25: h | F25: 入力欄が空欄なら各社の合計工数（給与計算＋資料回収＋顧客対応＋質問対応）を合計
B26: 総必要工数（月・難易度調整後） | D26: =SUMIF('案件進捗管理'!$D$6:$D$115,"A：標準",'案件進捗管理'!$Q$6:$Q$115)*'キャパシティ・必要人数'!$D$17+SUMIF('案件進捗管理'!$D$6:$D$115,"B：中程度",'案件進捗管理'!$Q$6:$Q$115)*'キャパシティ・必要人数'!$D$18+SUMIF('案件進捗管理'!$D$6:$D$115,"C：複雑",'案件進捗管理'!$Q$6:$Q$115)*'キャパシティ・必要人数'!$D$19+MAX(0,'キャパシティ・必要人数'!$D$25-SUMIF('案件進捗管理'!$D$6:$D$115,"A：標準",'案件進捗管理'!$Q$6:$Q$115)-SUMIF('案件進捗管理'!$D$6:$D$115,"B：中程度",'案件進捗管理'!$Q$6:$Q$115)-SUMIF('案件進捗管理'!$D$6:$D$115,"C：複雑",'案件進捗管理'!$Q$6:$Q$115))*'キャパシティ・必要人数'!$D$18 | E26: h | F26: 会社別総工数 × 難易度係数。難易度未判定の企業はB係数で暫定計上
B27: 現在移管済み工数（月） | D27: =SUMIFS('案件進捗管理'!$Q$6:$Q$115,'案件進捗管理'!$V$6:$V$115,">0") | E27: h | F27: 実運用開始日が入力済みの企業の工数合計
B28: 残工数（月） | D28: ='キャパシティ・必要人数'!$D$25-'キャパシティ・必要人数'!$D$27 | E28: h | F28: 会社別総工数 − 現在移管済み工数
B29: 1人あたり週有効稼働時間 | D29: ='キャパシティ・必要人数'!$D$12*(1-'キャパシティ・必要人数'!$D$13) | E29: h | F29: 週稼働可能時間 ×（1 − 管理業務比率）
B30: 1人あたり処理可能工数（月） | D30: ='キャパシティ・必要人数'!$D$29*'キャパシティ・必要人数'!$D$20 | E30: h | F30: 1人あたり週有効稼働時間 × 月換算係数
B31: 週あたり処理可能工数（チーム） | D31: =('キャパシティ・必要人数'!$D$10+'キャパシティ・必要人数'!$D$11)*'キャパシティ・必要人数'!$D$29-'キャパシティ・必要人数'!$D$14-'キャパシティ・必要人数'!$D$15 | E31: h | F31: （秘書＋ワーカー）× 週有効稼働時間 − 教育工数 − 品質確認工数
B32: 月あたり処理可能工数（チーム） | D32: ='キャパシティ・必要人数'!$D$31*'キャパシティ・必要人数'!$D$20 | E32: h | F32: 週あたり処理可能工数 × 月換算係数
B33: 1社あたり平均工数（難易度調整後） | D33: =IF(COUNTIF('案件進捗管理'!$Q$6:$Q$115,">0")=0,"",'キャパシティ・必要人数'!$D$26/COUNTIF('案件進捗管理'!$Q$6:$Q$115,">0")) | E33: h | F33: 総必要工数 ÷ 工数入力済み社数。※工数未入力の社が多いうちは参考値（要確認）
B34: 現在人数で処理可能な企業数 | D34: =IF('キャパシティ・必要人数'!$D$33="","",ROUNDDOWN('キャパシティ・必要人数'!$D$32/'キャパシティ・必要人数'!$D$33,0)) | E34: 社 | F34: 月あたり処理可能工数 ÷ 1社あたり平均工数（＝維持できる社数）
B35: 週あたり処理可能社数 | D35: =IF('キャパシティ・必要人数'!$D$33="","",'キャパシティ・必要人数'!$D$31/'キャパシティ・必要人数'!$D$33) | E35: 社/週 | F35: 週あたり処理可能工数 ÷ 1社あたり平均工数
B36: 月あたり移管可能件数 | D36: =IF('キャパシティ・必要人数'!$D$33="","",MAX(0,ROUNDDOWN(('キャパシティ・必要人数'!$D$32-'キャパシティ・必要人数'!$D$27)/('キャパシティ・必要人数'!$D$33+'キャパシティ・必要人数'!$D$16),0))) | E36: 社/月 | F36: （月あたり処理可能工数 − 現在移管済み工数）÷（1社あたり平均工数 ＋ 移管1社あたり追加工数）
B37: 1人あたり処理可能社数（月） | D37: =IF('キャパシティ・必要人数'!$D$33="","",'キャパシティ・必要人数'!$D$30/'キャパシティ・必要人数'!$D$33) | E37: 社/人 | F37: 1人あたり処理可能工数（月）÷ 1社あたり平均工数
B38: 必要追加人数 | D38: =IF('キャパシティ・必要人数'!$D$26=0,"",MAX(0,ROUNDUP(('キャパシティ・必要人数'!$D$26-'キャパシティ・必要人数'!$D$32)/'キャパシティ・必要人数'!$D$30,0))) | E38: 名 | F38: （総必要工数 − 月あたり処理可能工数）÷ 1人あたり処理可能工数（月）
B39: 現在の移管ペース（社/週） | D39: =IF(TODAY()<DATE(2026,9,9),"",COUNTIFS('案件進捗管理'!$V$6:$V$115,">0")/MIN(8,MAX(1,ROUNDDOWN((TODAY()-DATE(2026,9,9))/7,0)+1))) | E39: 社/週 | F39: 実運用開始済み社数 ÷ 9/9からの経過週数（最大8週）
B40: 完全移管までの残社数 | D40: ='キャパシティ・必要人数'!$D$24-COUNTIFS('案件進捗管理'!$X$6:$X$115,">0") | E40: 社 | F40: 対象企業総数 − 完全移管日が入力済みの社数
A42: ③ 体制判定（自動）
B43: =IF('キャパシティ・必要人数'!$D$26=0,"要確認：会社別工数が未入力のため判定できません（案件進捗管理シートに工数を入力してください）",IF('キャパシティ・必要人数'!$D$38=0,"OK：現在の人員（"&('キャパシティ・必要人数'!$D$10+'キャパシティ・必要人数'!$D$11)&"名）で対象企業を処理可能な試算です ／月あたり移管可能件数 "&'キャパシティ・必要人数'!$D$36&" 社","要増員：追加 "&'キャパシティ・必要人数'!$D$38&"名が必要（暫定試算） 現在人数で処理可能なのは "&'キャパシティ・必要人数'!$D$34&" 社／月あたり移管可能件数 "&'キャパシティ・必要人数'!$D$36&" 社"))
...

Sheet KPI
A1: KPI ダッシュボード（An-field様 給与計算業務 完全移管）
A2: 進捗は3軸で評価します：①件数進捗（各ステータス到達社数）②工数進捗（移管できた工数）③自走進捗（An-field様の日常的な確認なしで運用できる社数）
A3: ※本シートの件数・工数・人数はすべて【暫定計画値】です。会社別工数・実績確認後に更新してください（確定値ではありません）。
A4: 【重要】10月＝完全移管ではありません。10月は「先行企業 実運用・対象企業拡大」フェーズです。
A6: ① KPIサマリー（自動集計 ／ 集計元：案件進捗管理・キャパシティ・週間スケジュール）
B7: 総企業数 | G7: 情報整理済み企業数 | L7: 引継ぎ中企業数 | Q7: 初回計算済み企業数
B8: =COUNTA('案件進捗管理'!$B$6:$B$115) | G8: =SUMPRODUCT(('案件進捗管理'!$D$6:$D$115<>"")*('案件進捗管理'!$D$6:$D$115<>"未判定")*('案件進捗管理'!$Q$6:$Q$115>0)) | L8: =COUNTIF('案件進捗管理'!$E$6:$E$115,"2. 引継ぎ中") | Q8: =SUMPRODUCT((('案件進捗管理'!$T$6:$T$115=TRUE)+('案件進捗管理'!$T$6:$T$115="TRUE")>0)*1)
B9: 対象 100〜110社 | G9: 難易度が判定され、工数が入力済みの社数 | L9: ステータス＝2. 引継ぎ中 | Q9: 初回計算完了にチェックが入った社数
B11: 検証中企業数 | G11: 自走可能企業数 | L11: 完全移管企業数 | Q11: 実運用累計企業数
B12: =COUNTIF('案件進捗管理'!$E$6:$E$115,"4. 検証中") | G12: =COUNTIFS('案件進捗管理'!$W$6:$W$115,">0") | L12: =COUNTIFS('案件進捗管理'!$X$6:$X$115,">0") | Q12: =COUNTIFS('案件進捗管理'!$V$6:$V$115,">0")
B13: ステータス＝4. 検証中 | G13: ＝担当者単独で処理できた企業数（自走可能日が入力済み） | L13: ＝An-field様の確認が不要だった企業数（完全移管日が入力済み） | Q13: 実運用開始日が入力済みの社数
B15: 移管済み工数 | G15: 残工数 | L15: 総実績工数 | Q15: 1社あたり平均工数
B16: ='キャパシティ・必要人数'!$D$27 | G16: ='キャパシティ・必要人数'!$D$28 | L16: =IF(COUNT('週間スケジュール'!$H$7:$H$14)=0,"",SUM('週間スケジュール'!$H$7:$H$14)) | Q16: =IF(COUNTIF('案件進捗管理'!$Q$6:$Q$115,">0")=0,"",SUM('案件進捗管理'!$Q$6:$Q$115)/COUNTIF('案件進捗管理'!$Q$6:$Q$115,">0"))
B17: ＝処理できた総工数（実運用開始済み企業の月間工数合計） | G17: 会社別総工数 − 移管済み工数（月） | L17: 週間スケジュールの実績工数の累計 | Q17: 工数入力済み社の単純平均（月）。難易度調整後はキャパシティシート参照
B19: 現在人数 | G19: 追加必要人数 | L19: 月あたり移管可能件数 | Q19: 1人あたり処理可能社数
B20: ='キャパシティ・必要人数'!$D$10+'キャパシティ・必要人数'!$D$11 | G20: ='キャパシティ・必要人数'!$D$38 | L20: ='キャパシティ・必要人数'!$D$36 | Q20: ='キャパシティ・必要人数'!$D$37
B21: 秘書チーム＋追加ワーカー | G21: （総必要工数 − 月あたり処理可能工数）÷ 1人あたり処理可能工数（月） | L21: （月処理可能工数 − 移管済み工数）÷（1社平均工数 ＋ 移管1社あたり追加工数） | Q21: 1人あたり処理可能工数（月）÷ 1社あたり平均工数
A24: ② 週次データ（グラフ元データ ／ 実績工数のみ手入力）
B25: 週 | D25: 期間終了日 | F25: 計画実運用累計 （暫定） | H25: 実績実運用累計 （自動） | J25: 計画工数 （暫定） | L25: 実績工数 【入力】 | N25: 移管済み工数 累計（自動） | P25: 件数進捗率 （自動） | R25: 工数進捗率 （自動）
B26: 第1週 | D26: 46278 | F26: 0 | H26: ='週間スケジュール'!$F$7 | J26: ='週間スケジュール'!$G$7 | L26: =IF('週間スケジュール'!$H$7="","",'週間スケジュール'!$H$7) | N26: =SUMPRODUCT(('案件進捗管理'!$V$6:$V$115<>"")*('案件進捗管理'!$V$6:$V$115<=$D26)*'案件進捗管理'!$Q$6:$Q$115) | P26: =IF('キャパシティ・必要人数'!$D$24=0,"",H26/'キャパシティ・必要人数'!$D$24) | R26: =IF('キャパシティ・必要人数'!$D$25=0,"",N26/'キャパシティ・必要人数'!$D$25)
B27: 第2週 | D27: 46285 | F27: 0 | H27: ='週間スケジュール'!$F$8 | J27: ='週間スケジュール'!$G$8 | L27: =IF('週間スケジュール'!$H$8="","",'週間スケジュール'!$H$8) | N27: =SUMPRODUCT(('案件進捗管理'!$V$6:$V$115<>"")*('案件進捗管理'!$V$6:$V$115<=$D27)*'案件進捗管理'!$Q$6:$Q$115) | P27: =IF('キャパシティ・必要人数'!$D$24=0,"",H27/'キャパシティ・必要人数'!$D$24) | R27: =IF('キャパシティ・必要人数'!$D$25=0,"",N27/'キャパシティ・必要人数'!$D$25)
B28: 第3週 | D28: 46292 | F28: 0 | H28: ='週間スケジュール'!$F$9 | J28: ='週間スケジュール'!$G$9 | L28: =IF('週間スケジュール'!$H$9="","",'週間スケジュール'!$H$9) | N28: =SUMPRODUCT(('案件進捗管理'!$V$6:$V$115<>"")*('案件進捗管理'!$V$6:$V$115<=$D28)*'案件進捗管理'!$Q$6:$Q$115) | P28: =IF('キャパシティ・必要人数'!$D$24=0,"",H28/'キャパシティ・必要人数'!$D$24) | R28: =IF('キャパシティ・必要人数'!$D$25=0,"",N28/'キャパシティ・必要人数'!$D$25)
B29: 第4週 | D29: 46299 | F29: 7 | H29: ='週間スケジュール'!$F$10 | J29: ='週間スケジュール'!$G$10 | L29: =IF('週間スケジュール'!$H$10="","",'週間スケジュール'!$H$10) | N29: =SUMPRODUCT(('案件進捗管理'!$V$6:$V$115<>"")*('案件進捗管理'!$V$6:$V$115<=$D29)*'案件進捗管理'!$Q$6:$Q$115) | P29: =IF('キャパシティ・必要人数'!$D$24=0,"",H29/'キャパシティ・必要人数'!$D$24) | R29: =IF('キャパシティ・必要人数'!$D$25=0,"",N29/'キャパシティ・必要人数'!$D$25)
B30: 第5週 | D30: 46306 | F30: 12 | H30: ='週間スケジュール'!$F$11 | J30: ='週間スケジュール'!$G$11 | L30: =IF('週間スケジュール'!$H$11="","",'週間スケジュール'!$H$11) | N30: =SUMPRODUCT(('案件進捗管理'!$V$6:$V$115<>"")*('案件進捗管理'!$V$6:$V$115<=$D30)*'案件進捗管理'!$Q$6:$Q$115) | P30: =IF('キャパシティ・必要人数'!$D$24=0,"",H30/'キャパシティ・必要人数'!$D$24) | R30: =IF('キャパシティ・必要人数'!$D$25=0,"",N30/'キャパシティ・必要人数'!$D$25)
B31: 第6週 | D31: 46313 | F31: 17 | H31: ='週間スケジュール'!$F$12 | J31: ='週間スケジュール'!$G$12 | L31: =IF('週間スケジュール'!$H$12="","",'週間スケジュール'!$H$12) | N31: =SUMPRODUCT(('案件進捗管理'!$V$6:$V$115<>"")*('案件進捗管理'!$V$6:$V$115<=$D31)*'案件進捗管理'!$Q$6:$Q$115) | P31: =IF('キャパシティ・必要人数'!$D$24=0,"",H31/'キャパシティ・必要人数'!$D$24) | R31: =IF('キャパシティ・必要人数'!$D$25=0,"",N31/'キャパシティ・必要人数'!$D$25)
B32: 第7週 | D32: 46320 | F32: 25 | H32: ='週間スケジュール'!$F$13 | J32: ='週間スケジュール'!$G$13 | L32: =IF('週間スケジュール'!$H$13="","",'週間スケジュール'!$H$13) | N32: =SUMPRODUCT(('案件進捗管理'!$V$6:$V$115<>"")*('案件進捗管理'!$V$6:$V$115<=$D32)*'案件進捗管理'!$Q$6:$Q$115) | P32: =IF('キャパシティ・必要人数'!$D$24=0,"",H32/'キャパシティ・必要人数'!$D$24) | R32: =IF('キャパシティ・必要人数'!$D$25=0,"",N32/'キャパシティ・必要人数'!$D$25)
B33: 第8週 | D33: 46326 | F33: 30 | H33: ='週間スケジュール'!$F$14 | J33: ='週間スケジュール'!$G$14 | L33: =IF('週間スケジュール'!$H$14="","",'週間スケジュール'!$H$14) | N33: =SUMPRODUCT(('案件進捗管理'!$V$6:$V$115<>"")*('案件進捗管理'!$V$6:$V$115<=$D33)*'案件進捗管理'!$Q$6:$Q$115) | P33: =IF('キャパシティ・必要人数'!$D$24=0,"",H33/'キャパシティ・必要人数'!$D$24) | R33: =IF('キャパシティ・必要人数'!$D$25=0,"",N33/'キャパシティ・必要人数'!$D$25)
B34: 合計 / 最終 | F34: =MAX(F26:F33) | H34: =MAX(H26:H33) | J34: =SUM(J26:J33) | L34: =IF(COUNT(L26:L33)=0,"",SUM(L26:L33)) | N34: =MAX(N26:N33) | P34: =MAX(P26:P33) | R34: =MAX(R26:R33)
A36: ③ 移管ステータス別 企業数（グラフ①元データ）
B38: 区分 | C38: 1. 未着手 | D38: 2. 引継ぎ中 | E38: 3. 初回計算 | F38: 4. 検証中 | G38: 5. 自走可能 | H38: 6. 完全移管
B39: 全社 | C39: =COUNTIF('案件進捗管理'!$E$6:$E$115,"1. 未着手") | D39: =COUNTIF('案件進捗管理'!$E$6:$E$115,"2. 引継ぎ中") | E39: =COUNTIF('案件進捗管理'!$E$6:$E$115,"3. 初回計算") | F39: =COUNTIF('案件進捗管理'!$E$6:$E$115,"4. 検証中") | G39: =COUNTIF('案件進捗管理'!$E$6:$E$115,"5. 自走可能") | H39: =COUNTIF('案件進捗管理'!$E$6:$E$115,"6. 完全移管")
B40: 構成比 | C40: =IF('キャパシティ・必要人数'!$D$24=0,"",C39/'キャパシティ・必要人数'!$D$24) | D40: =IF('キャパシティ・必要人数'!$D$24=0,"",D39/'キャパシティ・必要人数'!$D$24) | E40: =IF('キャパシティ・必要人数'!$D$24=0,"",E39/'キャパシティ・必要人数'!$D$24) | F40: =IF('キャパシティ・必要人数'!$D$24=0,"",F39/'キャパシティ・必要人数'!$D$24) | G40: =IF('キャパシティ・必要人数'!$D$24=0,"",G39/'キャパシティ・必要人数'!$D$24) | H40: =IF('キャパシティ・必要人数'!$D$24=0,"",H39/'キャパシティ・必要人数'!$D$24)
A42: ④ 処理能力比較（グラフ④元データ）
B43: 区分 | C43: 月あたり工数（h）
B44: 現在処理能力（月） | C44: ='キャパシティ・必要人数'!$D$32 | D44: 必要処理能力が現在処理能力を上回る場合は増員が必要です。不足分 ÷ 1人あたり月間有効稼働時間 ＝ 追加必要人数（キャパシティシートで自動算出）。
B45: 必要処理能力（月） | C45: ='キャパシティ・必要人数'!$D$26
A47: ⑤ グラフ（①ステータス別／②実運用推移／③工数 計画vs実績／④処理能力／⑤件数進捗vs工数進捗）
A108: 【10月末時点で確認すべき判断材料】 ① 実運用済み企業数 ② 自走可能企業数 ③ 完全移管企業数 ④ 残企業数 ⑤ 残工数 ⑥ 必要追加人数 ⑦ 1人あたり処理可能工数・1人あたり処理可能社数 ⑧ 月あたり移管可能件数・今後の移管ペース（社/週） → ⑦⑧の詳細は「キャパシティ・必要人数」シートで自動算出されます。
A109: 【企業数だけで見ないための重点KPI（10/12週〜）】① 処理できた総工数 ＝ KPIカード「移管済み工数」 ② An-field様の確認が不要だった企業数 ＝ KPIカード「完全移管企業数」 ③ 担当者単独で処理できた企業数 ＝ KPIカード「自走可能企業数」
A110: 【進捗管理ルール】このプロジェクトは「何社移管したか」だけでは判断しません。①件数進捗（何社が各ステータスまで進んだか）②工数進捗（全体工数のうち何時間分を移管できたか）③自走進捗（何社がAn-field様の日常的な確認なしで運用できるか）の3軸で評価します。
...
