Workbook

Sheet 週間スケジュール
A1: 給与計算対象企業 | B1: 給与計算_作業時間.xlsx
A2: An-field様 給与計算業務 完全移管 週間進行管理（2026/9/9 ～ 12/31） | N2: =E25 | O2: 引継ぎ完了件数
A3: 9月＝全社情報整理・優先順位決定・先行企業引継ぎ・テスト計算・採用準備 ／ 10月＝先行企業 実運用・対象企業拡大・運用精度確認（★ママワークス採用開始） ／ 11月＝移管ペース本格化・ワーカー戦力化・年末調整準備 ／ 12月＝年末調整・賞与対応・完全移管の見極め
A4: ※本シートの件数・工数・人数はすべて【暫定計画値】です。会社別工数・実績確認後に更新してください（確定値ではありません）。
A5: 【重要】10月＝完全移管ではありません。10月は「先行企業 実運用・対象企業拡大」フェーズです。 ママワークスでの追加ワーカー採用は2026年10月開始。11〜12月は年末調整・賞与対応と並行して移管を進めます。
A6: 計画（期間・フェーズ・対応内容） | D6: 暫定計画値 ／ 実績入力 ／ 自動計算 | L6: 完了条件・運用管理（手入力）
A7: 期間 | B7: フェーズ | C7: 主な対応内容 | D7: 引継ぎ対象企業数 | E7: 引継ぎ完了企業数 | F7: 実運用完了企業数 | G7: 計画工数 | H7: 実績工数 | I7: 必要人数 | J7: 実働人数 | K7: 1社あたり平均工数 | L7: 完了条件 | M7: ステータス | N7: 課題 | O7: 次週アクション
A8: 2026/9/9（水）～9/13（日） | B8: 情報整理・移管設計 | C8: ・全社情報の整理 ・案件ごとの難易度、工数の把握 ・先行移管企業の選定 ・追加人員の採用開始 | D8: 0 | E8: 0 | F8: =SUMPRODUCT(('案件進捗管理'!$V$6:$V$115<>"")*('案件進捗管理'!$V$6:$V$115<=DATE(2026,9,13))) | G8: 5 | I8: =IF(OR(NOT(ISNUMBER(G8)),'キャパシティ・必要人数'!$D$29=0),"",ROUNDUP(G8/'キャパシティ・必要人数'!$D$29,0)) | K8: =IF(OR(E8="",N(E8)=0,H8=""),"",H8/E8) | L8: ・対象企業の全体像が整理されている ・先行移管する企業が決まっている ・会社別の工数確認を開始できている | M8: 未着手
A9: 2026/9/14（月）～9/20（日） | B9: 先行企業引継ぎ・工数計測 | C9: ・先行企業の業務引き継ぎ ・実務レクチャー、工数計測 ・追加ワーカーの選考 | D9: 0 | E9: 0 | F9: =SUMPRODUCT(('案件進捗管理'!$V$6:$V$115<>"")*('案件進捗管理'!$V$6:$V$115<=DATE(2026,9,20))) | G9: 5 | I9: =IF(OR(NOT(ISNUMBER(G9)),'キャパシティ・必要人数'!$D$29=0),"",ROUNDUP(G9/'キャパシティ・必要人数'!$D$29,0)) | K9: =IF(OR(E9="",N(E9)=0,H9=""),"",H9/E9) | L9: ・先行企業の業務内容を担当者が把握できている ・実際の業務を通じて工数計測を開始できている ・追加人員の選考が進んでいる | M9: 未着手
A10: 2026/9/24（木）～9/27（日） | B10: テスト計算・移管モデル確立 | C10: ・先行企業のテスト計算 ・運用課題、必要工数の確認 ・移管体制、必要人数の整理 | D10: 6 | F10: =SUMPRODUCT(('案件進捗管理'!$V$6:$V$115<>"")*('案件進捗管理'!$V$6:$V$115<=DATE(2026,9,27))) | G10: 15 | I10: =IF(OR(NOT(ISNUMBER(G10)),'キャパシティ・必要人数'!$D$29=0),"",ROUNDUP(G10/'キャパシティ・必要人数'!$D$29,0)) | K10: =IF(OR(E10="",N(E10)=0,H10=""),"",H10/E10) | L10: ・先行企業のテスト計算が進んでいる ・案件ごとの難易度や必要工数が見えている ・秘書チーム／ワーカーの役割分担が整理されている | M10: 未着手
A11: 2026/9/28（月）～10/4（日） | B11: 先行企業 実運用開始 | C11: ・テスト済み企業の実運用開始 ・実運用を通じた課題確認 ・追加ワーカーの教育 | D11: 0 | F11: =SUMPRODUCT(('案件進捗管理'!$V$6:$V$115<>"")*('案件進捗管理'!$V$6:$V$115<=DATE(2026,10,4))) | G11: 15 | I11: =IF(OR(NOT(ISNUMBER(G11)),'キャパシティ・必要人数'!$D$29=0),"",ROUNDUP(G11/'キャパシティ・必要人数'!$D$29,0)) | K11: =IF(OR(E11="",N(E11)=0,H11=""),"",H11/E11) | L11: ・テスト済み企業で実運用を開始できている ・資料回収〜納品までの一連の流れを確認できている ・実運用上の課題が把握できている | M11: 未着手
A12: 2026/10/5（月）～10/11（日） | B12: 企業引継ぎ・工数計測 | C12: ・先行企業の運用安定化 ・次の対象企業の引き継ぎ開始 ・運用方法の改善 | D12: 未定 | F12: =SUMPRODUCT(('案件進捗管理'!$V$6:$V$115<>"")*('案件進捗管理'!$V$6:$V$115<=DATE(2026,10,11))) | G12: 5 | I12: =IF(OR(NOT(ISNUMBER(G12)),'キャパシティ・必要人数'!$D$29=0),"",ROUNDUP(G12/'キャパシティ・必要人数'!$D$29,0)) | K12: =IF(OR(E12="",N(E12)=0,H12=""),"",H12/E12) | L12: ・先行企業の運用が安定し始めている ・次の対象企業の引き継ぎを開始できている ・追加ワーカーへの業務移管が進んでいる | M12: 未着手
A13: 2026/10/12（月）～10/18（日） | B13: テスト計算・移管モデル確立 | C13: ・実運用企業の拡大 ・追加企業のテスト、引き継ぎ ・実績工数の確認 | D13: 未定 | F13: =SUMPRODUCT(('案件進捗管理'!$V$6:$V$115<>"")*('案件進捗管理'!$V$6:$V$115<=DATE(2026,10,18))) | G13: 5 | I13: =IF(OR(NOT(ISNUMBER(G13)),'キャパシティ・必要人数'!$D$29=0),"",ROUNDUP(G13/'キャパシティ・必要人数'!$D$29,0)) | K13: =IF(OR(E13="",N(E13)=0,H13=""),"",H13/E13) | L13: ・実運用する企業数を拡大できている ・担当者単独で対応できる企業が増えている ・実績をもとに会社別工数を更新できている | M13: 未着手
A14: 2026/10/19（月）～10/25（日） | B14: 実運用対象拡大 | C14: ・対象企業のさらなる拡大 ・人員配置、運用体制の見直し ・今後の移管ペース確認 | D14: 未定 | F14: =SUMPRODUCT(('案件進捗管理'!$V$6:$V$115<>"")*('案件進捗管理'!$V$6:$V$115<=DATE(2026,10,25))) | G14: 未定 | I14: =IF(OR(NOT(ISNUMBER(G14)),'キャパシティ・必要人数'!$D$29=0),"",ROUNDUP(G14/'キャパシティ・必要人数'!$D$29,0)) | K14: =IF(OR(E14="",N(E14)=0,H14=""),"",H14/E14) | L14: ・対象企業の移管を継続して拡大できている ・現在の人員で対応可能な範囲が見えている ・追加人員が必要か判断できる状態になっている | M14: 未着手
A15: 2026/10/26（月）～10/31（土） | B15: 実運用対象拡大 | C15: ・10月の実運用実績を整理 ・残課題、必要人員を確認 ・今後の移管方針を決定 | D15: 未定 | F15: =SUMPRODUCT(('案件進捗管理'!$V$6:$V$115<>"")*('案件進捗管理'!$V$6:$V$115<=DATE(2026,10,31))) | G15: 未定 | I15: =IF(OR(NOT(ISNUMBER(G15)),'キャパシティ・必要人数'!$D$29=0),"",ROUNDUP(G15/'キャパシティ・必要人数'!$D$29,0)) | K15: =IF(OR(E15="",N(E15)=0,H15=""),"",H15/E15) | L15: ・10月の移管・実運用実績が整理されている ・残っている企業、課題、必要工数が把握できている ・今後の移管ペースと必要体制を判断できている | M15: 未着手
A16: 2026/11/1（日）～11/8（日） | B16: 第3グループ移管・新規採用者受入 | C16: ・第3グループの引継ぎ開始 ・ママワークス採用者の受入、初期教育 ・定型案件のワーカー移管継続 ・10月の残課題解消 | D16: 未定 | F16: =SUMPRODUCT(('案件進捗管理'!$V$6:$V$115<>"")*('案件進捗管理'!$V$6:$V$115<=DATE(2026,11,8))) | G16: 未定 | I16: =IF(OR(NOT(ISNUMBER(G16)),'キャパシティ・必要人数'!$D$29=0),"",ROUNDUP(G16/'キャパシティ・必要人数'!$D$29,0)) | K16: =IF(OR(E16="",N(E16)=0,H16=""),"",H16/E16) | L16: ・ママワークス採用者が業務を開始できている ・第3グループの引継ぎが開始されている ・10月に出た運用課題が解消されている 【暫定目安】実運用累計 35社程度 | M16: 未着手
A17: 2026/11/9（月）～11/15（日） | B17: 実運用拡大・年末調整準備 | C17: ・実運用企業の追加 ・年末調整の対象企業、スケジュール確認 ・年末調整に必要な資料回収フローの確認 ・ワーカーの担当範囲拡大 | D17: 未定 | F17: =SUMPRODUCT(('案件進捗管理'!$V$6:$V$115<>"")*('案件進捗管理'!$V$6:$V$115<=DATE(2026,11,15))) | G17: 未定 | I17: =IF(OR(NOT(ISNUMBER(G17)),'キャパシティ・必要人数'!$D$29=0),"",ROUNDUP(G17/'キャパシティ・必要人数'!$D$29,0)) | K17: =IF(OR(E17="",N(E17)=0,H17=""),"",H17/E17) | L17: ・年末調整の対象企業と必要資料が全件整理されている ・資料回収フローが確認できている 【暫定目安】実運用累計 40社程度 | M17: 未着手
A18: 2026/11/16（月）～11/22（日） | B18: 実運用拡大・ワーカー自走化 | C18: ・定型企業のワーカー単独運用開始 ・秘書チームは高難易度案件、管理業務へ集中 ・属人化案件の洗い出し ・バックアップ担当の拡充 | D18: 未定 | F18: =SUMPRODUCT(('案件進捗管理'!$V$6:$V$115<>"")*('案件進捗管理'!$V$6:$V$115<=DATE(2026,11,22))) | G18: 未定 | I18: =IF(OR(NOT(ISNUMBER(G18)),'キャパシティ・必要人数'!$D$29=0),"",ROUNDUP(G18/'キャパシティ・必要人数'!$D$29,0)) | K18: =IF(OR(E18="",N(E18)=0,H18=""),"",H18/E18) | L18: ・ワーカー単独で運用できる企業が増えている ・属人化案件が特定されている ・全案件にバックアップ担当が設定されている 【暫定目安】実運用累計 45社程度 | M18: 未着手
A19: 2026/11/23（月）～11/29（日） | B19: 11月総括・処理能力再計算 | C19: ・11月実績の集計 ・会社別、難易度別の平均工数を更新 ・処理能力の再計算 ・追加採用要否の再判定 ・12月（年末調整、賞与）の体制確定 | D19: 未定 | F19: =SUMPRODUCT(('案件進捗管理'!$V$6:$V$115<>"")*('案件進捗管理'!$V$6:$V$115<=DATE(2026,11,29))) | G19: 未定 | I19: =IF(OR(NOT(ISNUMBER(G19)),'キャパシティ・必要人数'!$D$29=0),"",ROUNDUP(G19/'キャパシティ・必要人数'!$D$29,0)) | K19: =IF(OR(E19="",N(E19)=0,H19=""),"",H19/E19) | L19: ・11月時点の処理能力と必要人数が数値で確定している ・12月の年末調整、賞与対応の体制が決まっている 【暫定目安】実運用累計 50社程度 | M19: 未着手
A20: 2026/11/30（月）～12/6（日） | B20: 年末調整・賞与計算 対応開始 | C20: ・年末調整の申告書回収状況の確認 ・賞与計算対象企業の確認 ・イレギュラー対応の切り分け ・秘書チームによる重点チェック体制の構築 | D20: 未定 | F20: =SUMPRODUCT(('案件進捗管理'!$V$6:$V$115<>"")*('案件進捗管理'!$V$6:$V$115<=DATE(2026,12,6))) | G20: 未定 | I20: =IF(OR(NOT(ISNUMBER(G20)),'キャパシティ・必要人数'!$D$29=0),"",ROUNDUP(G20/'キャパシティ・必要人数'!$D$29,0)) | K20: =IF(OR(E20="",N(E20)=0,H20=""),"",H20/E20) | L20: ・年末調整、賞与の対象企業と締切が全件把握できている ・重点チェック対象が決まっている 【暫定目安】実運用累計 55社程度 | M20: 未着手
A21: 2026/12/7（月）～12/13（日） | B21: 年末調整 実施・実運用拡大 | C21: ・年末調整のデータ入力、計算 ・賞与計算の実施 ・通常給与計算との並行運用 ・実運用企業の追加 | D21: 未定 | F21: =SUMPRODUCT(('案件進捗管理'!$V$6:$V$115<>"")*('案件進捗管理'!$V$6:$V$115<=DATE(2026,12,13))) | G21: 未定 | I21: =IF(OR(NOT(ISNUMBER(G21)),'キャパシティ・必要人数'!$D$29=0),"",ROUNDUP(G21/'キャパシティ・必要人数'!$D$29,0)) | K21: =IF(OR(E21="",N(E21)=0,H21=""),"",H21/E21) | L21: ・年末調整、賞与計算が計画どおり進んでいる ・通常給与計算に遅延が出ていない 【暫定目安】実運用累計 60社程度 | M21: 未着手
A22: 2026/12/14（月）～12/20（日） | B22: 賞与計算・完全移管判定開始 | C22: ・賞与支給日対応 ・年末調整の還付、徴収額の確認 ・完全移管の判定基準に沿った企業評価 ・自走可能企業の確定 | D22: 未定 | F22: =SUMPRODUCT(('案件進捗管理'!$V$6:$V$115<>"")*('案件進捗管理'!$V$6:$V$115<=DATE(2026,12,20))) | G22: 未定 | I22: =IF(OR(NOT(ISNUMBER(G22)),'キャパシティ・必要人数'!$D$29=0),"",ROUNDUP(G22/'キャパシティ・必要人数'!$D$29,0)) | K22: =IF(OR(E22="",N(E22)=0,H22=""),"",H22/E22) | L22: ・完全移管の定義を満たした企業が判定できている ・自走可能企業が確定している 【暫定目安】実運用累計 65社程度 | M22: 未着手
A23: 2026/12/21（月）～12/27（日） | B23: 年末対応ピーク・完全移管確定 | C23: ・年内最終の給与計算、納品 ・年末調整の最終確認 ・残課題の洗い出し ・年始スケジュールの確認 | D23: 未定 | F23: =SUMPRODUCT(('案件進捗管理'!$V$6:$V$115<>"")*('案件進捗管理'!$V$6:$V$115<=DATE(2026,12,27))) | G23: 未定 | I23: =IF(OR(NOT(ISNUMBER(G23)),'キャパシティ・必要人数'!$D$29=0),"",ROUNDUP(G23/'キャパシティ・必要人数'!$D$29,0)) | K23: =IF(OR(E23="",N(E23)=0,H23=""),"",H23/E23) | L23: ・年内の給与計算、納品が全件完了している ・年末調整の最終確認が終わっている 【暫定目安】実運用累計 70社程度 | M23: 未着手
A24: 2026/12/28（月）～12/31（木） | B24: 12月総括・次フェーズ（2027年1月以降）方針判断 | C24: ・12月実績の集計 ・完全移管企業数の確定 ・残企業数、残工数の算出 ・2027年1月以降の移管計画と必要人員の確定 | D24: 未定 | F24: =SUMPRODUCT(('案件進捗管理'!$V$6:$V$115<>"")*('案件進捗管理'!$V$6:$V$115<=DATE(2026,12,31))) | G24: 未定 | I24: =IF(OR(NOT(ISNUMBER(G24)),'キャパシティ・必要人数'!$D$29=0),"",ROUNDUP(G24/'キャパシティ・必要人数'!$D$29,0)) | K24: =IF(OR(E24="",N(E24)=0,H24=""),"",H24/E24) | L24: 【12月末ゴール】以下がすべて確定している ・完全移管企業数／自走可能企業数／実運用済み企業数 ・残企業数／残工数／必要追加人数 ・1人あたり処理能力と今後の移管ペース 【暫定目安】実運用累計 75社程度 | M24: 未着手
A25: 合計 / 最終（暫定計画値） | D25: =SUM(D8:D24) | E25: =IF(COUNT(E8:E24)=0,"",SUM(E8:E24)) | F25: =MAX(F8:F24) | G25: =SUM(G8:G24) | H25: =IF(COUNT(H8:H24)=0,"",SUM(H8:H24)) | I25: =MAX(I8:I24) | J25: =IF(COUNT(J8:J24)=0,"",MAX(J8:J24)) | K25: =IF(OR(E25="",H25=""),"",H25/E25) | L25: ※合計は暫定計画値の積み上げです。件数目標のために無理に移管せず、実工数と品質をもとに件数を調整してください。
A27: 【完全移管の定義】「給与計算ができる状態」ではありません。資料回収・顧客対応・質問対応・勤怠取得・給与計算・チェック・納品・進捗管理・担当者管理・欠員時の再配置まで、An-field様が日常的に管理しなくても回る状態を指します。
A28: 【進捗は3軸で評価】①件数進捗＝何社が各ステータスまで進んだか ②工数進捗＝全体工数のうち何時間分の業務を移管できたか ③自走進捗＝何社がAn-field様の日常的な確認なしで運用できる状態になったか。「何社移管したか」だけでは判断しないでください。
A29: 【計画の考え方】「毎週○社移管する」という件数ありきの計画にはしません。会社ごとに給与計算工数・やり取り時間・資料回収時間・質問対応時間・使用ツール・締日・支給日・例外処理・特殊ルール・難易度が異なるため、『会社別総工数 × 難易度 ÷ 担当者処理能力』で処理能力を算出し、件数は結果として決まります。
A30: 【暫定値の扱い】引継ぎ対象企業数・計画工数・必要人数は暫定計画値です。実工数が不明なものは「未定」「要確認」のままで構いません（必要人数は自動的に空欄になります）。実績入力後に再計算してください。必要人数は『計画工数 ÷ 1人あたり週有効稼働時間』で自動算出しています。
A31: 【11〜12月について】11月は移管ペース本格化・ワーカー戦力化・年末調整準備、12月は年末調整・賞与対応と完全移管の見極めです。★ママワークスでの追加ワーカー採用は10月開始のため、戦力化は11月以降を想定しています（キャパシティシート④を参照）。

Sheet ガントチャート
A1: An-field様 給与計算業務 完全移管 ガントチャート（2026/9/9 ～ 12/31）
A2: 色分け：情報整理＝グレー／採用＝紫／引継ぎ＝青／テスト＝水色／実運用＝緑／検証＝オレンジ／リスク＝赤
A3: ※本シートの件数・工数・人数はすべて【暫定計画値】です。会社別工数・実績確認後に更新してください（確定値ではありません）。
A4: 【重要】10月＝完全移管ではありません。10月は「先行企業 実運用・対象企業拡大」フェーズです。 ママワークスでの追加ワーカー採用は2026年10月開始。11〜12月は年末調整・賞与対応と並行して移管を進めます。
A5: 【凡例】区分の色 | I5: 情報整理 | O5: 採用 | U5: 引継ぎ | AA5: テスト | AG5: 実運用 | AM5: 検証 | AS5: リスク
A6: 月フェーズ | H6: 9月：全社情報整理・優先順位決定・先行企業引継ぎ・テスト計算・採用準備 | AD6: 10月：先行企業 実運用・対象企業拡大・運用精度確認／ママワークス採用開始 ※完全移管ではありません | BI6: 11月：移管ペース本格化・ワーカー戦力化・年末調整準備 | CM6: 12月：年末調整・賞与対応・完全移管の見極め
A7: No. | B7: タスク | C7: 区分 | D7: 開始日 （暫定） | E7: 終了日 （暫定） | F7: 日数 | G7: 進捗率 【入力】 | H7: 第1週 9/9～9/13 | M7: 第2週 9/14～9/20 | T7: 第3週 9/21～9/27 | AA7: 第4週 9/28～10/4 | AH7: 第5週 10/5～10/11 | AO7: 第6週 10/12～10/18 | AV7: 第7週 10/19～10/25 | BC7: 第8週 10/26～10/31 | BI7: 第9週 11/1～11/8 | BQ7: 第10週 11/9～11/15 | BX7: 第11週 11/16～11/22 | CE7: 第12週 11/23～11/29 | CL7: 第13週 11/30～12/6 | CS7: 第14週 12/7～12/13 | CZ7: 第15週 12/14～12/20 | DG7: 第16週 12/21～12/27 | DN7: 第17週 12/28～12/31
H8: 46274 | I8: 46275 | J8: 46276 | K8: 46277 | L8: 46278 | M8: 46279 | N8: 46280 | O8: 46281 | P8: 46282 | Q8: 46283 | R8: 46284 | S8: 46285 | T8: 46286 | U8: 46287 | V8: 46288 | W8: 46289 | X8: 46290 | Y8: 46291 | Z8: 46292 | AA8: 46293 | AB8: 46294 | AC8: 46295 | AD8: 46296 | AE8: 46297 | AF8: 46298 | AG8: 46299 | AH8: 46300 | AI8: 46301 | AJ8: 46302 | AK8: 46303 | AL8: 46304 | AM8: 46305 | AN8: 46306 | AO8: 46307 | AP8: 46308 | AQ8: 46309 | AR8: 46310 | AS8: 46311 | AT8: 46312 | AU8: 46313 | AV8: 46314 | AW8: 46315 | AX8: 46316 | AY8: 46317 | AZ8: 46318 | BA8: 46319 | BB8: 46320 | BC8: 46321 | BD8: 46322 | BE8: 46323 | BF8: 46324 | BG8: 46325 | BH8: 46326 | BI8: 46327 | BJ8: 46328 | BK8: 46329 | BL8: 46330 | BM8: 46331 | BN8: 46332 | BO8: 46333 | BP8: 46334 | BQ8: 46335 | BR8: 46336 | BS8: 46337 | BT8: 46338 | BU8: 46339 | BV8: 46340 | BW8: 46341 | BX8: 46342 | BY8: 46343 | BZ8: 46344 | CA8: 46345 | CB8: 46346 | CC8: 46347 | CD8: 46348 | CE8: 46349 | CF8: 46350 | CG8: 46351 | CH8: 46352 | CI8: 46353 | CJ8: 46354 | CK8: 46355 | CL8: 46356 | CM8: 46357 | CN8: 46358 | CO8: 46359 | CP8: 46360 | CQ8: 46361 | CR8: 46362 | CS8: 46363 | CT8: 46364 | CU8: 46365 | CV8: 46366 | CW8: 46367 | CX8: 46368 | CY8: 46369 | CZ8: 46370 | DA8: 46371 | DB8: 46372 | DC8: 46373 | DD8: 46374 | DE8: 46375 | DF8: 46376 | DG8: 46377 | DH8: 46378 | DI8: 46379 | DJ8: 46380 | DK8: 46381 | DL8: 46382 | DM8: 46383 | DN8: 46384 | DO8: 46385 | DP8: 46386 | DQ8: 46387
H9: 水 | I9: 木 | J9: 金 | K9: 土 | L9: 日 | M9: 月 | N9: 火 | O9: 水 | P9: 木 | Q9: 金 | R9: 土 | S9: 日 | T9: 月 | U9: 火 | V9: 水 | W9: 木 | X9: 金 | Y9: 土 | Z9: 日 | AA9: 月 | AB9: 火 | AC9: 水 | AD9: 木 | AE9: 金 | AF9: 土 | AG9: 日 | AH9: 月 | AI9: 火 | AJ9: 水 | AK9: 木 | AL9: 金 | AM9: 土 | AN9: 日 | AO9: 月 | AP9: 火 | AQ9: 水 | AR9: 木 | AS9: 金 | AT9: 土 | AU9: 日 | AV9: 月 | AW9: 火 | AX9: 水 | AY9: 木 | AZ9: 金 | BA9: 土 | BB9: 日 | BC9: 月 | BD9: 火 | BE9: 水 | BF9: 木 | BG9: 金 | BH9: 土 | BI9: 日 | BJ9: 月 | BK9: 火 | BL9: 水 | BM9: 木 | BN9: 金 | BO9: 土 | BP9: 日 | BQ9: 月 | BR9: 火 | BS9: 水 | BT9: 木 | BU9: 金 | BV9: 土 | BW9: 日 | BX9: 月 | BY9: 火 | BZ9: 水 | CA9: 木 | CB9: 金 | CC9: 土 | CD9: 日 | CE9: 月 | CF9: 火 | CG9: 水 | CH9: 木 | CI9: 金 | CJ9: 土 | CK9: 日 | CL9: 月 | CM9: 火 | CN9: 水 | CO9: 木 | CP9: 金 | CQ9: 土 | CR9: 日 | CS9: 月 | CT9: 火 | CU9: 水 | CV9: 木 | CW9: 金 | CX9: 土 | CY9: 日 | CZ9: 月 | DA9: 火 | DB9: 水 | DC9: 木 | DD9: 金 | DE9: 土 | DF9: 日 | DG9: 月 | DH9: 火 | DI9: 水 | DJ9: 木 | DK9: 金 | DL9: 土 | DM9: 日 | DN9: 月 | DO9: 火 | DP9: 水 | DQ9: 木
A10: 1 | B10: 全社情報整理 | C10: 情報整理 | D10: 46274 | E10: 46285 | F10: =E10-D10+1 | G10: 0
A11: 2 | B11: 会社別工数確認 | C11: 情報整理 | D11: 46274 | E11: 46387 | F11: =E11-D11+1 | G11: 0
A12: 3 | B12: 難易度分類 | C12: 情報整理 | D12: 46274 | E12: 46292 | F12: =E12-D12+1 | G12: 0
A13: 4 | B13: 優先順位決定 | C13: 情報整理 | D13: 46274 | E13: 46278 | F13: =E13-D13+1 | G13: 0
A14: 5 | B14: 先行企業選定 | C14: 情報整理 | D14: 46274 | E14: 46278 | F14: =E14-D14+1 | G14: 0
A15: 6 | B15: 先行企業引継ぎ | C15: 引継ぎ | D15: 46279 | E15: 46292 | F15: =E15-D15+1 | G15: 0
A16: 7 | B16: テスト計算 | C16: テスト | D16: 46282 | E16: 46299 | F16: =E16-D16+1 | G16: 0
A17: 8 | B17: 追加ワーカー募集（既存ルート） | C17: 採用 | D17: 46274 | E17: 46295 | F17: =E17-D17+1 | G17: 0
A18: 9 | B18: ママワークス求人準備 | C18: 採用 | D18: 46286 | E18: 46295 | F18: =E18-D18+1 | G18: 0
A19: 10 | B19: ★ママワークス募集開始・応募受付 | C19: 採用 | D19: 46296 | E19: 46356 | F19: =E19-D19+1 | G19: 0
A20: 11 | B20: ママワークス面接・選考 | C20: 採用 | D20: 46307 | E20: 46369 | F20: =E20-D20+1 | G20: 0
A21: 12 | B21: 採用者オンボーディング・教育 | C21: 採用 | D21: 46321 | E21: 46387 | F21: =E21-D21+1 | G21: 0
... A39: 30 | B39: 採用遅延・欠員・属人化リスク監視 | C39: リスク | D39: 46274 | E39: 46387 | F39: =E39-D39+1 | G39: 0
AA40: ▲ 9/28 先行企業 実運用開始 | BH40: ▲ 10/31 10月総括 | DB40: ▲ 12/31 12月総括・次フェーズ判断
AD41: ▲ 10/1 ★ママワークス 追加ワーカー採用開始
A43: 【9月】9/13：全社一覧化・先行候補選定 │ 9/20：先行引継ぎ開始・実工数計測開始 │ 9/27：難易度A/B/C基準確定・役割分担確定 │ 9/28：先行企業 実運用開始
A44: 【10月】10/1：★ママワークス募集開始 │ 10/11：先行企業安定化・第2グループ引継ぎ │ 10/18：An-field様側の確認工数測定 │ 10/25：処理能力再計算・追加採用要否判定 │ 10/31：10月総括
A45: 【11月】11/8：第3グループ移管開始・採用者受入 │ 11/15：年末調整の対象・必要資料を確定 │ 11/22：ワーカー単独運用の拡大 │ 11/29：11月総括・処理能力再計算・12月体制確定
A46: 【12月】12/6：年末調整/賞与の対象・締切を全件把握 │ 12/20：年末調整・賞与計算完了 │ 12/27：年内最終の給与計算・納品完了 │ 12/31：完全移管企業数・残工数・必要追加人数を確定
A47: 【重要】12月末のゴールは「100〜110社の完全移管」ではありません。完全移管企業数・残企業数・残工数・必要追加人数・1人あたり処理能力が数値で確定し、2027年1月以降の移管ペースを設計できる状態がゴールです。
A48: 【凡例】色付きバー＝暫定計画期間 ／ 薄い黄色＝手入力（進捗率） ／ グレーの列＝土日 ／ 縦線＝9/28 実運用開始・10/1 ママワークス採用開始・10/31 10月総括・12/31 12月総括

Sheet 案件進捗管理
A1: 案件進捗管理（対象 100〜110社） An-field様 給与計算業務 完全移管
A2: 【完全移管の定義】資料回収・給与計算・不明点対応・顧問先とのやり取り・納品・担当者管理まで、An-field様の日常的な管理なしで完結する状態。 ※10月＝完全移管ではありません（10月は先行企業 実運用・対象企業拡大）。
A3: ※工数は1社あたり【月間】の想定時間（h）。現時点で実工数が不明なものは空欄のまま「要確認」とし、実績入力後に再計算してください（暫定値）。企業名は仮名称です。対象が100社の場合は不要行を削除してください。
A4: No. | B4: 企業名 | C4: 優先順位 | D4: 難易度 | E4: 移管ステータス | F4: 秘書／ワーカー区分 | G4: 主担当 | H4: バックアップ担当 | I4: 給与計算ソフト | J4: 勤怠ツール | K4: 締日 | L4: 支給日 | M4: 給与計算工数 | N4: 資料回収工数 | O4: 顧客対応工数 | P4: 質問対応工数 | Q4: 合計工数 | R4: チェックシート受領 | S4: 業務レクチャー完了 | T4: 初回計算完了 | U4: 検証完了 | V4: 実運用開始日 | W4: 自走可能日 | X4: 完全移管日 | Y4: 課題 | Z4: 備考
A5: 例 | B5: （記入例）株式会社サンプル | C5: 1：最優先 | D5: B：中程度 | E5: 2. 引継ぎ中 | F5: 秘書チーム中心 | G5: 山田 | H5: 佐藤 | I5: セルズ給与 | J5: KING OF TIME | K5: 末日 | L5: 翌月15日 | M5: 4 | N5: 1.5 | O5: 1 | P5: 0.5 | Q5: =SUM(M5:P5) | R5: TRUE | S5: TRUE | T5: FALSE | U5: FALSE | Y5: 賞与月の計算ルールが未確認 | Z5: 従業員32名／例外：時給者の深夜割増あり
A6: 1 | B6: 企業001 | E6: 1. 未着手 | Q6: =SUM(M6:P6) | R6: FALSE | S6: FALSE | T6: FALSE | U6: FALSE
A7: 2 | B7: 企業002 | E7: 1. 未着手 | Q7: =SUM(M7:P7) | R7: FALSE | S7: FALSE | T7: FALSE | U7: FALSE
A8: 3 | B8: 企業003 | E8: 1. 未着手 | Q8: =SUM(M8:P8) | R8: FALSE | S8: FALSE | T8: FALSE | U8: FALSE
A9: 4 | B9: 企業004 | E9: 1. 未着手 | Q9: =SUM(M9:P9) | R9: FALSE | S9: FALSE | T9: FALSE | U9: FALSE
A10: 5 | B10: 企業005 | E10: 1. 未着手 | Q10: =SUM(M10:P10) | R10: FALSE | S10: FALSE | T10: FALSE | U10: FALSE
A11: 6 | B11: 企業006 | E11: 1. 未着手 | Q11: =SUM(M11:P11) | R11: FALSE | S11: FALSE | T11: FALSE | U11: FALSE
A12: 7 | B12: 企業007 | E12: 1. 未着手 | Q12: =SUM(M12:P12) | R12: FALSE | S12: FALSE | T12: FALSE | U12: FALSE
A13: 8 | B13: 企業008 | E13: 1. 未着手 | Q13: =SUM(M13:P13) | R13: FALSE | S13: FALSE | T13: FALSE | U13: FALSE
A14: 9 | B14: 企業009 | E14: 1. 未着手 | Q14: =SUM(M14:P14) | R14: FALSE | S14: FALSE | T14: FALSE | U14: FALSE
A15: 10 | B15: 企業010 | E15: 1. 未着手 | Q15: =SUM(M15:P15) | R15: FALSE | S15: FALSE | T15: FALSE | U15: FALSE
A16: 11 | B16: 企業011 | E16: 1. 未着手 | Q16: =SUM(M16:P16) | R16: FALSE | S16: FALSE | T16: FALSE | U16: FALSE
A17: 12 | B17: 企業012 | E17: 1. 未着手 | Q17: =SUM(M17:P17) | R17: FALSE | S17: FALSE | T17: FALSE | U17: FALSE
... A115: 110 | B115: 企業110 | E115: 1. 未着手 | Q115: =SUM(M115:P115) | R115: FALSE | S115: FALSE | T115: FALSE | U115: FALSE

Sheet キャパシティ・必要人数
A1: キャパシティ・必要人数 試算（An-field様 給与計算業務 完全移管）
A2: 算出ロジック：会社別総工数 × 難易度 ÷ 担当者処理能力 → 必要人数・週あたり処理可能社数・月あたり移管可能件数
A3: ※本シートの件数・工数・人数はすべて【暫定計画値】です。会社別工数・実績確認後に更新してください（確定値ではありません）。
A4: 【重要】10月＝完全移管ではありません。10月は「先行企業 実運用・対象企業拡大」フェーズです。 ママワークスでの追加ワーカー採用は2026年10月開始。11〜12月は年末調整・賞与対応と並行して移管を進めます。
A6: ① 入力項目（薄い黄色セルを入力 ／ すべて暫定値・要確認・実績入力後に再計算）
B7: 項目 | D7: 値 | E7: 単位 | F7: 説明・根拠
B8: 対象企業総数 | E8: 社 | F8: 【入力・空欄可】空欄の場合は案件進捗管理シートの企業名から自動集計します
B9: 会社別総工数（月・合計） | E9: h/月 | F9: 【入力・空欄可】空欄の場合は案件進捗管理シートの合計工数から自動集計します
B10: 秘書チーム人数 | D10: 3 | E10: 名 | F10: 全体管理・顧客対応・資料回収・質問対応・高難易度計算・教育・品質管理・納品管理・欠員時の再配置
B11: 追加ワーカー人数 | D11: 2 | E11: 名 | F11: 定型給与計算・チェックシートで自走可能な企業・手順が確立した業務
B12: 1人あたり週稼働可能時間 | D12: 30 | E12: h/週 | F12: 【暫定値・要確認】採用条件確定後に更新
B13: 管理業務比率 | D13: 0.2 | E13: ％ | F13: 【暫定値】打合せ・報告・調整など、直接作業以外に充てる割合
B14: 教育工数（週・チーム全体） | D14: 10 | E14: h/週 | F14: 【暫定値】追加ワーカー教育。処理可能工数から差し引く
B15: 品質確認工数（週・チーム全体） | D15: 8 | E15: h/週 | F15: 【暫定値】秘書チームによるチェック。処理可能工数から差し引く
B16: 移管1社あたり追加工数 | D16: 6 | E16: h/社 | F16: 【暫定値】引継ぎ・レクチャー・テスト計算・検証にかかる初期工数。月あたり移管可能件数の算定に使用
B17: 難易度係数 A：標準 | D17: 1 | E17: 倍 | F17: 【暫定値】9/27までに基準確定。実績入力後に再計算
B18: 難易度係数 B：中程度 | D18: 1.3 | E18: 倍 | F18: 【暫定値】難易度未判定の企業にもこの係数を適用
B19: 難易度係数 C：複雑 | D19: 1.7 | E19: 倍 | F19: 【暫定値】特殊ルール・例外処理が多い企業
B20: 月換算係数（週→月） | D20: 4.33 | E20: 週/月 | F20: 1ヶ月＝約4.33週
A22: ② 自動計算（グレーのセル ／ 入力値と案件進捗管理シートから算出）
B23: 項目 | D23: 値 | E23: 単位 | F23: 計算式・考え方
B24: 対象企業総数（採用値） | D24: =IF('キャパシティ・必要人数'!$D$8="",COUNTA('案件進捗管理'!$B$6:$B$115),'キャパシティ・必要人数'!$D$8) | E24: 社 | F24: 入力欄が空欄なら案件進捗管理シートから自動集計
B25: 会社別総工数（採用値・月） | D25: =IF('キャパシティ・必要人数'!$D$9="",SUM('案件進捗管理'!$Q$6:$Q$115),'キャパシティ・必要人数'!$D$9) | E25: h | F25: 入力欄が空欄なら各社の合計工数（給与計算＋資料回収＋顧客対応＋質問対応）を合計
B26: 総必要工数（月・難易度調整後） | D26: =SUMIF('案件進捗管理'!$D$6:$D$115,"A：標準",'案件進捗管理'!$Q$6:$Q$115)*'キャパシティ・必要人数'!$D$17+SUMIF('案件進捗管理'!$D$6:$D$115,"B：中程度",'案件進捗管理'!$Q$6:$Q$115)*'キャパシティ・必要人数'!$D$18+SUMIF('案件進捗管理'!$D$6:$D$115,"C：複雑",'案件進捗管理'!$Q$6:$Q$115)*'キャパシティ・必要人数'!$D$19+MAX(0,'キャパシティ・必要人数'!$D$25-SUMIF('案件進捗管理'!$D$6:$D$115,"A：標準",'案件進捗管理'!$Q$6:$Q$115)-SUMIF('案件進捗管理'!$D$6:$D$115,"B：中程度",'案件進捗管理'!$Q$6:$Q$115)-SUMIF('案件進捗管理'!$D$6:$D$115,"C：複雑",'案件進捗管理'!$Q$6:$Q$115))*'キャパシティ・必要人数'!$D$18 | E26: h | F26: 会社別総工数 × 難易度係数。難易度未判定の企業はB係数で暫定計上
B27: 現在移管済み工数（月） | D27: =SUMIFS('案件進捗管理'!$Q$6:$Q$115,'案件進捗管理'!$V$6:$V$115,">0") | E27: h | F27: 実運用開始日が入力済みの企業の工数合計
B28: 残工数（月） | D28: ='キャパシティ・必要人数'!$D$25-'キャパシティ・必要人数'!$D$27 | E28: h | F28: 会社別総工数 − 現在移管済み工数
B29: 1人あたり週有効稼働時間 | D29: ='キャパシティ・必要人数'!$D$12*(1-'キャパシティ・必要人数'!$D$13) | E29: h | F29: 週稼働可能時間 ×（1 − 管理業務比率）
B30: 1人あたり処理可能工数（月） | D30: ='キャパシティ・必要人数'!$D$29*'キャパシティ・必要人数'!$D$20 | E30: h | F30: 1人あたり週有効稼働時間 × 月換算係数
B31: 週あたり処理可能工数（チーム） | D31: =('キャパシティ・必要人数'!$D$10+'キャパシティ・必要人数'!$D$11)*'キャパシティ・必要人数'!$D$29-'キャパシティ・必要人数'!$D$14-'キャパシティ・必要人数'!$D$15 | E31: h | F31: （秘書＋ワーカー）× 週有効稼働時間 − 教育工数 − 品質確認工数
B32: 月あたり処理可能工数（チーム） | D32: ='キャパシティ・必要人数'!$D$31*'キャパシティ・必要人数'!$D$20 | E32: h | F32: 週あたり処理可能工数 × 月換算係数
B33: 1社あたり平均工数（難易度調整後） | D33: =IF(COUNTIF('案件進捗管理'!$Q$6:$Q$115,">0")=0,"",'キャパシティ・必要人数'!$D$26/COUNTIF('案件進捗管理'!$Q$6:$Q$115,">0")) | E33: h | F33: 総必要工数 ÷ 工数入力済み社数。※工数未入力の社が多いうちは参考値（要確認）
B34: 現在人数で処理可能な企業数 | D34: =IF('キャパシティ・必要人数'!$D$33="","",ROUNDDOWN('キャパシティ・必要人数'!$D$32/'キャパシティ・必要人数'!$D$33,0)) | E34: 社 | F34: 月あたり処理可能工数 ÷ 1社あたり平均工数（＝維持できる社数）
B35: 週あたり処理可能社数 | D35: =IF('キャパシティ・必要人数'!$D$33="","",'キャパシティ・必要人数'!$D$31/'キャパシティ・必要人数'!$D$33) | E35: 社/週 | F35: 週あたり処理可能工数 ÷ 1社あたり平均工数
B36: 月あたり移管可能件数 | D36: =IF('キャパシティ・必要人数'!$D$33="","",MAX(0,ROUNDDOWN(('キャパシティ・必要人数'!$D$32-'キャパシティ・必要人数'!$D$27)/('キャパシティ・必要人数'!$D$33+'キャパシティ・必要人数'!$D$16),0))) | E36: 社/月 | F36: （月あたり処理可能工数 − 現在移管済み工数）÷（1社あたり平均工数 ＋ 移管1社あたり追加工数）
B37: 1人あたり処理可能社数（月） | D37: =IF('キャパシティ・必要人数'!$D$33="","",'キャパシティ・必要人数'!$D$30/'キャパシティ・必要人数'!$D$33) | E37: 社/人 | F37: 1人あたり処理可能工数（月）÷ 1社あたり平均工数
B38: 必要追加人数 | D38: =IF('キャパシティ・必要人数'!$D$26=0,"",MAX(0,ROUNDUP(('キャパシティ・必要人数'!$D$26-'キャパシティ・必要人数'!$D$32)/'キャパシティ・必要人数'!$D$30,0))) | E38: 名 | F38: （総必要工数 − 月あたり処理可能工数）÷ 1人あたり処理可能工数（月）
B39: 現在の移管ペース（社/週） | D39: =IF(TODAY()<DATE(2026,9,9),"",COUNTIFS('案件進捗管理'!$V$6:$V$115,">0")/MIN(8,MAX(1,ROUNDDOWN((TODAY()-DATE(2026,9,9))/7,0)+1))) | E39: 社/週 | F39: 実運用開始済み社数 ÷ 9/9からの経過週数（最大8週）
B40: 完全移管までの残社数 | D40: ='キャパシティ・必要人数'!$D$24-COUNTIFS('案件進捗管理'!$X$6:$X$115,">0") | E40: 社 | F40: 対象企業総数 − 完全移管日が入力済みの社数
A42: ③ 体制判定（自動）
B43: =IF('キャパシティ・必要人数'!$D$26=0,"要確認：会社別工数が未入力のため判定できません（案件進捗管理シートに工数を入力してください）",IF('キャパシティ・必要人数'!$D$38=0,"OK：現在の人員（"&('キャパシティ・必要人数'!$D$10+'キャパシティ・必要人数'!$D$11)&"名）で対象企業を処理可能な試算です ／月あたり移管可能件数 "&'キャパシティ・必要人数'!$D$36&" 社","要増員：追加 "&'キャパシティ・必要人数'!$D$38&"名が必要（暫定試算） 現在人数で処理可能なのは "&'キャパシティ・必要人数'!$D$34&" 社／月あたり移管可能件数 "&'キャパシティ・必要人数'!$D$36&" 社"))
...

Sheet KPI
A1: KPI ダッシュボード（An-field様 給与計算業務 完全移管 ／ 2026年9月〜12月）
A2: 進捗は3軸で評価します：①件数進捗（各ステータス到達社数）②工数進捗（移管できた工数）③自走進捗（An-field様の日常的な確認なしで運用できる社数）
A3: ※本シートの件数・工数・人数はすべて【暫定計画値】です。会社別工数・実績確認後に更新してください（確定値ではありません）。
A4: 【重要】10月＝完全移管ではありません。10月は「先行企業 実運用・対象企業拡大」フェーズです。 ママワークスでの追加ワーカー採用は2026年10月開始。11〜12月は年末調整・賞与対応と並行して移管を進めます。
A6: ① KPIサマリー（自動集計 ／ 集計元：案件進捗管理・キャパシティ・週間スケジュール）
B7: 総企業数 | G7: 情報整理済み企業数 | L7: 引継ぎ中企業数 | Q7: 初回計算済み企業数
B8: =COUNTA('案件進捗管理'!$B$6:$B$115) | G8: =SUMPRODUCT(('案件進捗管理'!$D$6:$D$115<>"")*('案件進捗管理'!$D$6:$D$115<>"未判定")*('案件進捗管理'!$Q$6:$Q$115>0)) | L8: =COUNTIF('案件進捗管理'!$E$6:$E$115,"2. 引継ぎ中") | Q8: =SUMPRODUCT((('案件進捗管理'!$T$6:$T$115=TRUE)+('案件進捗管理'!$T$6:$T$115="TRUE")>0)*1)
B9: 対象 100〜110社 | G9: 難易度が判定され、工数が入力済みの社数 | L9: ステータス＝2. 引継ぎ中 | Q9: 初回計算完了にチェックが入った社数
B11: 検証中企業数 | G11: 自走可能企業数 | L11: 完全移管企業数 | Q11: 実運用累計企業数
B12: =COUNTIF('案件進捗管理'!$E$6:$E$115,"4. 検証中") | G12: =COUNTIFS('案件進捗管理'!$W$6:$W$115,">0") | L12: =COUNTIFS('案件進捗管理'!$X$6:$X$115,">0") | Q12: =COUNTIFS('案件進捗管理'!$V$6:$V$115,">0")
B13: ステータス＝4. 検証中 | G13: ＝担当者単独で処理できた企業数（自走可能日が入力済み） | L13: ＝An-field様の確認が不要だった企業数（完全移管日が入力済み） | Q13: 実運用開始日が入力済みの社数
B15: 移管済み工数 | G15: 残工数 | L15: 総実績工数 | Q15: 1社あたり平均工数
B16: ='キャパシティ・必要人数'!$D$27 | G16: ='キャパシティ・必要人数'!$D$28 | L16: =IF(COUNT('週間スケジュール'!$H$8:$H$24)=0,"",SUM('週間スケジュール'!$H$8:$H$24)) | Q16: =IF(COUNTIF('案件進捗管理'!$Q$6:$Q$115,">0")=0,"",SUM('案件進捗管理'!$Q$6:$Q$115)/COUNTIF('案件進捗管理'!$Q$6:$Q$115,">0"))
B17: ＝処理できた総工数（実運用開始済み企業の月間工数合計） | G17: 会社別総工数 − 移管済み工数（月） | L17: 週間スケジュールの実績工数の累計 | Q17: 工数入力済み社の単純平均（月）。難易度調整後はキャパシティシート参照
B19: 現在人数 | G19: 追加必要人数 | L19: 月あたり移管可能件数 | Q19: 1人あたり処理可能社数
B20: ='キャパシティ・必要人数'!$D$10+'キャパシティ・必要人数'!$D$11 | G20: ='キャパシティ・必要人数'!$D$38 | L20: ='キャパシティ・必要人数'!$D$36 | Q20: ='キャパシティ・必要人数'!$D$37
B21: 秘書チーム＋追加ワーカー | G21: （総必要工数 − 月あたり処理可能工数）÷ 1人あたり処理可能工数（月） | L21: （月処理可能工数 − 移管済み工数）÷（1社平均工数 ＋ 移管1社あたり追加工数） | Q21: 1人あたり処理可能工数（月）÷ 1社あたり平均工数
A24: ② 週次データ（グラフ元データ ／ 実績工数のみ手入力）
B25: 週 | D25: 期間終了日 | F25: 計画実運用累計 （暫定） | H25: 実績実運用累計 （自動） | J25: 計画工数 （暫定） | L25: 実績工数 【入力】 | N25: 移管済み工数 累計（自動） | P25: 件数進捗率 （自動） | R25: 工数進捗率 （自動）
B26: 第1週 | D26: 46278 | F26: 0 | H26: ='週間スケジュール'!$F$8 | J26: ='週間スケジュール'!$G$8 | L26: =IF('週間スケジュール'!$H$8="","",'週間スケジュール'!$H$8) | N26: =SUMPRODUCT(('案件進捗管理'!$V$6:$V$115<>"")*('案件進捗管理'!$V$6:$V$115<=$D26)*'案件進捗管理'!$Q$6:$Q$115) | P26: =IF('キャパシティ・必要人数'!$D$24=0,"",H26/'キャパシティ・必要人数'!$D$24) | R26: =IF('キャパシティ・必要人数'!$D$25=0,"",N26/'キャパシティ・必要人数'!$D$25)
B27: 第2週 | D27: 46285 | F27: 0 | H27: ='週間スケジュール'!$F$9 | J27: ='週間スケジュール'!$G$9 | L27: =IF('週間スケジュール'!$H$9="","",'週間スケジュール'!$H$9) | N27: =SUMPRODUCT(('案件進捗管理'!$V$6:$V$115<>"")*('案件進捗管理'!$V$6:$V$115<=$D27)*'案件進捗管理'!$Q$6:$Q$115) | P27: =IF('キャパシティ・必要人数'!$D$24=0,"",H27/'キャパシティ・必要人数'!$D$24) | R27: =IF('キャパシティ・必要人数'!$D$25=0,"",N27/'キャパシティ・必要人数'!$D$25)
B28: 第3週 | D28: 46292 | F28: 0 | H28: ='週間スケジュール'!$F$10 | J28: ='週間スケジュール'!$G$10 | L28: =IF('週間スケジュール'!$H$10="","",'週間スケジュール'!$H$10) | N28: =SUMPRODUCT(('案件進捗管理'!$V$6:$V$115<>"")*('案件進捗管理'!$V$6:$V$115<=$D28)*'案件進捗管理'!$Q$6:$Q$115) | P28: =IF('キャパシティ・必要人数'!$D$24=0,"",H28/'キャパシティ・必要人数'!$D$24) | R28: =IF('キャパシティ・必要人数'!$D$25=0,"",N28/'キャパシティ・必要人数'!$D$25)
B29: 第4週 | D29: 46299 | F29: 7 | H29: ='週間スケジュール'!$F$11 | J29: ='週間スケジュール'!$G$11 | L29: =IF('週間スケジュール'!$H$11="","",'週間スケジュール'!$H$11) | N29: =SUMPRODUCT(('案件進捗管理'!$V$6:$V$115<>"")*('案件進捗管理'!$V$6:$V$115<=$D29)*'案件進捗管理'!$Q$6:$Q$115) | P29: =IF('キャパシティ・必要人数'!$D$24=0,"",H29/'キャパシティ・必要人数'!$D$24) | R29: =IF('キャパシティ・必要人数'!$D$25=0,"",N29/'キャパシティ・必要人数'!$D$25)
B30: 第5週 | D30: 46306 | F30: 12 | H30: ='週間スケジュール'!$F$12 | J30: ='週間スケジュール'!$G$12 | L30: =IF('週間スケジュール'!$H$12="","",'週間スケジュール'!$H$12) | N30: =SUMPRODUCT(('案件進捗管理'!$V$6:$V$115<>"")*('案件進捗管理'!$V$6:$V$115<=$D30)*'案件進捗管理'!$Q$6:$Q$115) | P30: =IF('キャパシティ・必要人数'!$D$24=0,"",H30/'キャパシティ・必要人数'!$D$24) | R30: =IF('キャパシティ・必要人数'!$D$25=0,"",N30/'キャパシティ・必要人数'!$D$25)
B31: 第6週 | D31: 46313 | F31: 17 | H31: ='週間スケジュール'!$F$13 | J31: ='週間スケジュール'!$G$13 | L31: =IF('週間スケジュール'!$H$13="","",'週間スケジュール'!$H$13) | N31: =SUMPRODUCT(('案件進捗管理'!$V$6:$V$115<>"")*('案件進捗管理'!$V$6:$V$115<=$D31)*'案件進捗管理'!$Q$6:$Q$115) | P31: =IF('キャパシティ・必要人数'!$D$24=0,"",H31/'キャパシティ・必要人数'!$D$24) | R31: =IF('キャパシティ・必要人数'!$D$25=0,"",N31/'キャパシティ・必要人数'!$D$25)
B32: 第7週 | D32: 46320 | F32: 25 | H32: ='週間スケジュール'!$F$14 | J32: ='週間スケジュール'!$G$14 | L32: =IF('週間スケジュール'!$H$14="","",'週間スケジュール'!$H$14) | N32: =SUMPRODUCT(('案件進捗管理'!$V$6:$V$115<>"")*('案件進捗管理'!$V$6:$V$115<=$D32)*'案件進捗管理'!$Q$6:$Q$115) | P32: =IF('キャパシティ・必要人数'!$D$24=0,"",H32/'キャパシティ・必要人数'!$D$24) | R32: =IF('キャパシティ・必要人数'!$D$25=0,"",N32/'キャパシティ・必要人数'!$D$25)
B33: 第8週 | D33: 46326 | F33: 30 | H33: ='週間スケジュール'!$F$15 | J33: ='週間スケジュール'!$G$15 | L33: =IF('週間スケジュール'!$H$15="","",'週間スケジュール'!$H$15) | N33: =SUMPRODUCT(('案件進捗管理'!$V$6:$V$115<>"")*('案件進捗管理'!$V$6:$V$115<=$D33)*'案件進捗管理'!$Q$6:$Q$115) | P33: =IF('キャパシティ・必要人数'!$D$24=0,"",H33/'キャパシティ・必要人数'!$D$24) | R33: =IF('キャパシティ・必要人数'!$D$25=0,"",N33/'キャパシティ・必要人数'!$D$25)
B34: 第9週 | D34: 46334 | F34: 35 | H34: ='週間スケジュール'!$F$16 | J34: ='週間スケジュール'!$G$16 | L34: =IF('週間スケジュール'!$H$16="","",'週間スケジュール'!$H$16) | N34: =SUMPRODUCT(('案件進捗管理'!$V$6:$V$115<>"")*('案件進捗管理'!$V$6:$V$115<=$D34)*'案件進捗管理'!$Q$6:$Q$115) | P34: =IF('キャパシティ・必要人数'!$D$24=0,"",H34/'キャパシティ・必要人数'!$D$24) | R34: =IF('キャパシティ・必要人数'!$D$25=0,"",N34/'キャパシティ・必要人数'!$D$25)
B35: 第10週 | D35: 46341 | F35: 40 | H35: ='週間スケジュール'!$F$17 | J35: ='週間スケジュール'!$G$17 | L35: =IF('週間スケジュール'!$H$17="","",'週間スケジュール'!$H$17) | N35: =SUMPRODUCT(('案件進捗管理'!$V$6:$V$115<>"")*('案件進捗管理'!$V$6:$V$115<=$D35)*'案件進捗管理'!$Q$6:$Q$115) | P35: =IF('キャパシティ・必要人数'!$D$24=0,"",H35/'キャパシティ・必要人数'!$D$24) | R35: =IF('キャパシティ・必要人数'!$D$25=0,"",N35/'キャパシティ・必要人数'!$D$25)
B36: 第11週 | D36: 46348 | F36: 45 | H36: ='週間スケジュール'!$F$18 | J36: ='週間スケジュール'!$G$18 | L36: =IF('週間スケジュール'!$H$18="","",'週間スケジュール'!$H$18) | N36: =SUMPRODUCT(('案件進捗管理'!$V$6:$V$115<>"")*('案件進捗管理'!$V$6:$V$115<=$D36)*'案件進捗管理'!$Q$6:$Q$115) | P36: =IF('キャパシティ・必要人数'!$D$24=0,"",H36/'キャパシティ・必要人数'!$D$24) | R36: =IF('キャパシティ・必要人数'!$D$25=0,"",N36/'キャパシティ・必要人数'!$D$25)
B37: 第12週 | D37: 46355 | F37: 50 | H37: ='週間スケジュール'!$F$19 | J37: ='週間スケジュール'!$G$19 | L37: =IF('週間スケジュール'!$H$19="","",'週間スケジュール'!$H$19) | N37: =SUMPRODUCT(('案件進捗管理'!$V$6:$V$115<>"")*('案件進捗管理'!$V$6:$V$115<=$D37)*'案件進捗管理'!$Q$6:$Q$115) | P37: =IF('キャパシティ・必要人数'!$D$24=0,"",H37/'キャパシティ・必要人数'!$D$24) | R37: =IF('キャパシティ・必要人数'!$D$25=0,"",N37/'キャパシティ・必要人数'!$D$25)
B38: 第13週 | D38: 46362 | F38: 55 | H38: ='週間スケジュール'!$F$20 | J38: ='週間スケジュール'!$G$20 | L38: =IF('週間スケジュール'!$H$20="","",'週間スケジュール'!$H$20) | N38: =SUMPRODUCT(('案件進捗管理'!$V$6:$V$115<>"")*('案件進捗管理'!$V$6:$V$115<=$D38)*'案件進捗管理'!$Q$6:$Q$115) | P38: =IF('キャパシティ・必要人数'!$D$24=0,"",H38/'キャパシティ・必要人数'!$D$24) | R38: =IF('キャパシティ・必要人数'!$D$25=0,"",N38/'キャパシティ・必要人数'!$D$25)
B39: 第14週 | D39: 46369 | F39: 60 | H39: ='週間スケジュール'!$F$21 | J39: ='週間スケジュール'!$G$21 | L39: =IF('週間スケジュール'!$H$21="","",'週間スケジュール'!$H$21) | N39: =SUMPRODUCT(('案件進捗管理'!$V$6:$V$115<>"")*('案件進捗管理'!$V$6:$V$115<=$D39)*'案件進捗管理'!$Q$6:$Q$115) | P39: =IF('キャパシティ・必要人数'!$D$24=0,"",H39/'キャパシティ・必要人数'!$D$24) | R39: =IF('キャパシティ・必要人数'!$D$25=0,"",N39/'キャパシティ・必要人数'!$D$25)
B40: 第15週 | D40: 46376 | F40: 65 | H40: ='週間スケジュール'!$F$22 | J40: ='週間スケジュール'!$G$22 | L40: =IF('週間スケジュール'!$H$22="","",'週間スケジュール'!$H$22) | N40: =SUMPRODUCT(('案件進捗管理'!$V$6:$V$115<>"")*('案件進捗管理'!$V$6:$V$115<=$D40)*'案件進捗管理'!$Q$6:$Q$115) | P40: =IF('キャパシティ・必要人数'!$D$24=0,"",H40/'キャパシティ・必要人数'!$D$24) | R40: =IF('キャパシティ・必要人数'!$D$25=0,"",N40/'キャパシティ・必要人数'!$D$25)
B41: 第16週 | D41: 46383 | F41: 70 | H41: ='週間スケジュール'!$F$23 | J41: ='週間スケジュール'!$G$23 | L41: =IF('週間スケジュール'!$H$23="","",'週間スケジュール'!$H$23) | N41: =SUMPRODUCT(('案件進捗管理'!$V$6:$V$115<>"")*('案件進捗管理'!$V$6:$V$115<=$D41)*'案件進捗管理'!$Q$6:$Q$115) | P41: =IF('キャパシティ・必要人数'!$D$24=0,"",H41/'キャパシティ・必要人数'!$D$24) | R41: =IF('キャパシティ・必要人数'!$D$25=0,"",N41/'キャパシティ・必要人数'!$D$25)
B42: 第17週 | D42: 46387 | F42: 75 | H42: ='週間スケジュール'!$F$24 | J42: ='週間スケジュール'!$G$24 | L42: =IF('週間スケジュール'!$H$24="","",'週間スケジュール'!$H$24) | N42: =SUMPRODUCT(('案件進捗管理'!$V$6:$V$115<>"")*('案件進捗管理'!$V$6:$V$115<=$D42)*'案件進捗管理'!$Q$6:$Q$115) | P42: =IF('キャパシティ・必要人数'!$D$24=0,"",H42/'キャパシティ・必要人数'!$D$24) | R42: =IF('キャパシティ・必要人数'!$D$25=0,"",N42/'キャパシティ・必要人数'!$D$25)
B43: 合計 / 最終 | F43: =MAX(F26:F42) | H43: =MAX(H26:H42) | J43: =SUM(J26:J42) | L43: =IF(COUNT(L26:L42)=0,"",SUM(L26:L42)) | N43: =MAX(N26:N42) | P43: =MAX(P26:P42) | R43: =MAX(R26:R42)
A45: ③ 移管ステータス別 企業数（グラフ①元データ）
B47: 区分 | C47: 1. 未着手 | D47: 2. 引継ぎ中 | E47: 3. 初回計算 | F47: 4. 検証中 | G47: 5. 自走可能 | H47: 6. 完全移管
B48: 全社 | C48: =COUNTIF('案件進捗管理'!$E$6:$E$115,"1. 未着手") | D48: =COUNTIF('案件進捗管理'!$E$6:$E$115,"2. 引継ぎ中") | E48: =COUNTIF('案件進捗管理'!$E$6:$E$115,"3. 初回計算") | F48: =COUNTIF('案件進捗管理'!$E$6:$E$115,"4. 検証中") | G48: =COUNTIF('案件進捗管理'!$E$6:$E$115,"5. 自走可能") | H48: =COUNTIF('案件進捗管理'!$E$6:$E$115,"6. 完全移管")
...
