Workbook

Sheet 全体スケジュール
A1: 給与計算100案件 10月完全移行 週間スケジュール（全体）
A2: 対象：給与計算 約100案件／目標：2026年10月1日より弊社主体での完全運用開始（顧客の日常的な確認・対応を不要とする状態）
A3: ※本シートの「当週引き継ぎ件数」「想定稼働時間」「想定人数」は現時点の計画値・試算値であり、確定実績ではありません。
A4: 計画（期間・内容） | D4: 計画値（試算） ※確定実績ではありません | J4: 運用・進捗管理（手入力）
A5: 期間 | B5: フェーズ | C5: 主な対応内容 | D5: 当週引き継ぎ件数 | E5: 累計引き継ぎ件数 | F5: 進捗率 | G5: 想定稼働時間 | H5: 想定人数 | I5: 1人あたり想定稼働時間 | J5: 完了条件 | K5: ステータス | L5: 備考・課題
A6: 2026/8/24（月）～8/30（日） | B6: 体制構築・業務棚卸し・初期引き継ぎ | C6: ・担当者4名の体制確定 ・100案件の一覧化 ・案件ごとの難易度分類 ・使用システム分類 ・担当者割り振り ・業務フロー確認 ・代表案件を使ったレクチャー ・チェックリスト、各種フォーマット共有 ・顧客ごとの注意点整理 | D6: 10 | E6: 10 | F6: =E6/$B$21 | G6: 60 | H6: 4 | I6: =IF(ISNUMBER(G6),G6/H6,"") | J6: ・100案件の棚卸し完了 ・担当者割り振り完了 ・主要業務フローを担当者が理解 ・代表10案件の引き継ぎ完了 | K6: 未着手
A7: 2026/8/31（月）～9/6（日） | B7: 実案件の並走開始 | C7: ・実際の給与計算業務を担当者が実施 ・勤怠取得 ・チェックリスト更新 ・給与計算 ・顧客確認 ・納品 ・進捗管理更新 まで一連の流れを経験する | D7: 20 | E7: 30 | F7: =E7/$B$21 | G7: 90 | H7: 4 | I7: =IF(ISNUMBER(G7),G7/H7,"") | J7: ・30案件の引き継ぎ完了 ・標準案件について一連の処理が可能 ・不明点、例外処理を一覧化 | K7: 未着手
A8: 2026/9/7（月）～9/13（日） | B8: 引き継ぎ件数拡大 | C8: ・標準案件の引き継ぎを加速 ・複数システム案件への対応 ・KING OF TIME等の勤怠取得対応 ・顧客固有ルールの整理 ・担当者単独で処理できる案件を増加 | D8: 25 | E8: 55 | F8: =E8/$B$21 | G8: 100 | H8: 4 | I8: =IF(ISNUMBER(G8),G8/H8,"") | J8: ・55案件の引き継ぎ完了 ・標準案件は弊社主体で処理可能 ・例外案件の対応方法が整理されている | K8: 未着手
A9: 2026/9/14（月）～9/20（日） | B9: 本番想定での並走 | C9: ・顧客対応も含め弊社主体で運用 ・給与計算から納品まで一連で実施 ・クライアント側の確認工数を減らす ・ミス、差し戻し内容を記録 ・バックアップ担当者を設定 | D9: 25 | E9: 80 | F9: =E9/$B$21 | G9: 100 | H9: 4 | I9: =IF(ISNUMBER(G9),G9/H9,"") | J9: ・80案件の引き継ぎ完了 ・大半の案件を弊社主体で運用 ・主要な例外パターンへの対応方法確立 | K9: 未着手
A10: 2026/9/21（月）～9/27（日） | B10: 残案件引き継ぎ・全件移行 | C10: ・残り20案件を引き継ぎ ・難易度の高い案件を重点確認 ・100案件すべての担当者確定 ・バックアップ担当設定 ・不足情報、権限、ID・PW等の確認 ・顧客対応方法の最終確認 | D10: 20 | E10: 100 | F10: =E10/$B$21 | G10: 80 | H10: 4 | I10: =IF(ISNUMBER(G10),G10/H10,"") | J10: ・100案件すべて引き継ぎ完了 ・全案件の主担当、バックアップ担当決定 ・10月運用対象に未割り当て案件がない | K10: 未着手
A11: 2026/9/28（月）～9/30（水） | B11: 最終調整・リハーサル | C11: ・新規引き継ぎは行わない ・未解決事項の解消 ・差し戻し案件の修正 ・権限不足確認 ・チェックリスト不足確認 ・運用フロー最終確認 ・10月開始判定 ・緊急時のエスカレーションルール確認 | D11: 0 | E11: 100 | F11: =E11/$B$21 | G11: 50 | H11: 4 | I11: =IF(ISNUMBER(G11),G11/H11,"") | J11: ・全100案件が10月運用開始可能 ・未解決の重大課題がない ・担当者、バックアップ、エスカレーション先が明確 | K11: 未着手
A12: 2026/10/1（木）～ | B12: 完全運用開始 | C12: ・100案件を弊社側主体で運用 ・顧客対応 ・勤怠取得 ・給与計算 ・納品 ・進捗更新 まで一連で実施 | D12: 0 | E12: 100 | F12: =E12/$B$21 | G12: 運用フェーズ | H12: 4 | I12: =IF(ISNUMBER(G12),G12/H12,"") | J12: 【目標】クライアント側が原則として給与計算業務に日常的に介入しなくても運用できる状態 | K12: 未着手
A13: 合計 / 計画値 | D13: =SUM(D6:D12) | E13: =MAX(E6:E12) | F13: =E13/$B$21 | G13: =SUM(G6:G12) | H13: 4 | I13: =G13/H13 | J13: ※総工数480時間／1名あたり約120時間（週20～25時間想定）はいずれも計画値です。
A15: 【「引き継ぎ完了」の定義】 単に業務説明を受けた状態は「完了」ではありません。以下すべてを確認できた案件のみを「引き継ぎ完了」とします。 ①業務内容理解 ②勤怠情報取得可能 ③給与計算可能 ④チェックリスト更新可能 ⑤顧客対応方法理解 ⑥納品方法理解 ⑦進捗管理更新可能 ⑧担当者確定
A16: 【判定ルール①】2026年9月27日時点で100件の引き継ぎが完了していない場合、10月1日の完全移行に対して「リスクあり」と判定します。
A17: 【判定ルール②】2026年8月30日時点で必要な3～4名程度の運用体制が確保できていない場合、10月完全移行について「要再計画」と表示します。
A18: 【計画の考え方】9月末に引き継ぎを開始するのではなく、9月第4週（～9/27）までに100案件の引き継ぎを完了し、9月28日～30日は修正・確認・リハーサルのバッファ期間として使用します。
A19: 【凡例】 塗りなし＝計画（固定） ／ 薄い黄色＝手入力セル ／ 薄いグレー＝自動計算セル（数式） ／ 進捗率＝累計引き継ぎ件数÷総案件数 ／ 1人あたり想定稼働時間＝想定稼働時間÷想定人数
A21: 総案件数（分母・計画値） | B21: 100 | C21: ←進捗率の分母。案件数が変わる場合はこのセルのみ変更してください。

Sheet ガントチャート
A1: 給与計算100案件 10月完全移行 ガントチャート（2026/8/24 ～ 10/7）
A2: フェーズ色分け：準備＝グレー／引き継ぎ＝青／実運用・並走＝水色／確認・QA＝オレンジ／完了・本番＝緑 10月1日に縦線＝完全運用開始ライン
A3: ※開始日・終了日・日数はいずれも計画値（試算）です。実績は「進捗率」列に手入力して管理してください。
A4: 【凡例】フェーズ区分の色 | I4: 準備 | P4: 引き継ぎ | W4: 実運用・並走 | AD4: 確認・QA | AK4: 完了・本番 | AT4: ▼ 10/1 完全運用開始
A5: タスク基本情報（計画値） | H5: 第1週 8/24～8/30 | O5: 第2週 8/31～9/6 | V5: 第3週 9/7～9/13 | AC5: 第4週 9/14～9/20 | AJ5: 第5週 9/21～9/27 | AQ5: 第6週 9/28～10/4 | AX5: 第7週 10/5～10/7
A6: No. | B6: タスク | C6: フェーズ区分 | D6: 開始日 （計画） | E6: 終了日 （計画） | F6: 日数 | G6: 進捗率 【入力】 | H6: 46258 | I6: 46259 | J6: 46260 | K6: 46261 | L6: 46262 | M6: 46263 | N6: 46264 | O6: 46265 | P6: 46266 | Q6: 46267 | R6: 46268 | S6: 46269 | T6: 46270 | U6: 46271 | V6: 46272 | W6: 46273 | X6: 46274 | Y6: 46275 | Z6: 46276 | AA6: 46277 | AB6: 46278 | AC6: 46279 | AD6: 46280 | AE6: 46281 | AF6: 46282 | AG6: 46283 | AH6: 46284 | AI6: 46285 | AJ6: 46286 | AK6: 46287 | AL6: 46288 | AM6: 46289 | AN6: 46290 | AO6: 46291 | AP6: 46292 | AQ6: 46293 | AR6: 46294 | AS6: 46295 | AT6: 46296 | AU6: 46297 | AV6: 46298 | AW6: 46299 | AX6: 46300 | AY6: 46301 | AZ6: 46302
H7: 月 | I7: 火 | J7: 水 | K7: 木 | L7: 金 | M7: 土 | N7: 日 | O7: 月 | P7: 火 | Q7: 水 | R7: 木 | S7: 金 | T7: 土 | U7: 日 | V7: 月 | W7: 火 | X7: 水 | Y7: 木 | Z7: 金 | AA7: 土 | AB7: 日 | AC7: 月 | AD7: 火 | AE7: 水 | AF7: 木 | AG7: 金 | AH7: 土 | AI7: 日 | AJ7: 月 | AK7: 火 | AL7: 水 | AM7: 木 | AN7: 金 | AO7: 土 | AP7: 日 | AQ7: 月 | AR7: 火 | AS7: 水 | AT7: 木 | AU7: 金 | AV7: 土 | AW7: 日 | AX7: 月 | AY7: 火 | AZ7: 水
A8: 1 | B8: 担当者アサイン（4名体制確定） | C8: 準備 | D8: 46258 | E8: 46264 | F8: =E8-D8+1 | G8: 0
A9: 2 | B9: 100案件棚卸し | C9: 準備 | D9: 46258 | E9: 46264 | F9: =E9-D9+1 | G9: 0
A10: 3 | B10: 案件難易度分類（A/B/C） | C10: 準備 | D10: 46258 | E10: 46264 | F10: =E10-D10+1 | G10: 0
A11: 4 | B11: 担当割り振り | C11: 準備 | D11: 46258 | E11: 46264 | F11: =E11-D11+1 | G11: 0
A12: 5 | B12: 権限・ID/PW確認 | C12: 準備 | D12: 46258 | E12: 46278 | F12: =E12-D12+1 | G12: 0
A13: 6 | B13: チェックリスト整理 | C13: 準備 | D13: 46258 | E13: 46278 | F13: =E13-D13+1 | G13: 0
A14: 7 | B14: Word→Excel移行 | C14: 準備 | D14: 46258 | E14: 46285 | F14: =E14-D14+1 | G14: 0
A15: 8 | B15: 業務レクチャー | C15: 準備 | D15: 46258 | E15: 46271 | F15: =E15-D15+1 | G15: 0
A16: 9 | B16: 第1弾10件引き継ぎ | C16: 引き継ぎ | D16: 46258 | E16: 46264 | F16: =E16-D16+1 | G16: 0
A17: 10 | B17: 第2弾20件引き継ぎ | C17: 引き継ぎ | D17: 46265 | E17: 46271 | F17: =E17-D17+1 | G17: 0
A18: 11 | B18: 第3弾25件引き継ぎ | C18: 引き継ぎ | D18: 46272 | E18: 46278 | F18: =E18-D18+1 | G18: 0
A19: 12 | B19: 第4弾25件引き継ぎ | C19: 引き継ぎ | D19: 46279 | E19: 46285 | F19: =E19-D19+1 | G19: 0
... A29: 22 | B29: 10月完全運用開始 | C29: 完了・本番 | D29: 46296 | E29: 46302 | F29: =E29-D29+1 | G29: 0
A31: 【マイルストーン】 8/30：累計10件（10%） │ 9/6：累計30件（30%） │ 9/13：累計55件（55%） │ 9/20：累計80件（80%） │ 9/27：累計100件（100%）＝引き継ぎ完了期限 │ 9/30：10月開始判定
A32: 【重要】 9/28～9/30 は新規引き継ぎを行わないバッファ期間です。9/27時点で100件未完了の場合、10月1日の完全移行は「リスクあり」と判定します。
A33: 【凡例】 色付きバー＝計画期間（計画値） ／ 薄い黄色セル＝手入力（進捗率） ／ グレーの列＝土日 ／ ゴールドの縦線＝2026/10/1 完全運用開始

Sheet 案件進捗管理
A1: 案件進捗管理（給与計算100案件）
A2: 「引き継ぎ完了」＝①業務内容理解 ②勤怠情報取得可能 ③給与計算可能 ④チェックリスト更新可能 ⑤顧客対応方法理解 ⑥納品方法理解 ⑦進捗管理更新可能 ⑧担当者確定 のすべてを満たした状態。説明を受けただけの状態は「完了」ではありません。
A3: ※顧客名は仮名称（案件001～案件100）です。実顧客名に置き換えてご利用ください。 チェック列は Google スプレッドシートで I6:N105 を選択 →［挿入］→［チェックボックス］でチェックボックス化できます。
A4: No. | B4: 顧客名 | C4: 担当者 | D4: バックアップ担当 | E4: 難易度 | F4: 給与計算ソフト | G4: 勤怠取得方法 | H4: チェックリスト形式 | I4: 業務レクチャー | J4: 勤怠取得確認 | K4: 給与計算確認 | L4: 顧客対応確認 | M4: 納品確認 | N4: 進捗表更新確認 | O4: 単独運用可否 | P4: 引き継ぎ完了日 | Q4: 課題 | R4: 備考
A5: 例 | B5: （記入例）株式会社サンプル | C5: 山田 | D5: 佐藤 | E5: B：中程度 | F5: セルズ給与 | G5: KING OF TIME | H5: Excel | I5: TRUE | J5: TRUE | K5: TRUE | L5: FALSE | M5: FALSE | N5: FALSE | O5: 条件付き | Q5: 賞与月の計算ルールが未確認 | R5: 毎月5日締／15日支給・従業員32名
A6: 1 | B6: 案件001 | I6: FALSE | J6: FALSE | K6: FALSE | L6: FALSE | M6: FALSE | N6: FALSE
A7: 2 | B7: 案件002 | I7: FALSE | J7: FALSE | K7: FALSE | L7: FALSE | M7: FALSE | N7: FALSE
A8: 3 | B8: 案件003 | I8: FALSE | J8: FALSE | K8: FALSE | L8: FALSE | M8: FALSE | N8: FALSE
A9: 4 | B9: 案件004 | I9: FALSE | J9: FALSE | K9: FALSE | L9: FALSE | M9: FALSE | N9: FALSE
A10: 5 | B10: 案件005 | I10: FALSE | J10: FALSE | K10: FALSE | L10: FALSE | M10: FALSE | N10: FALSE
A11: 6 | B11: 案件006 | I11: FALSE | J11: FALSE | K11: FALSE | L11: FALSE | M11: FALSE | N11: FALSE
A12: 7 | B12: 案件007 | I12: FALSE | J12: FALSE | K12: FALSE | L12: FALSE | M12: FALSE | N12: FALSE
A13: 8 | B13: 案件008 | I13: FALSE | J13: FALSE | K13: FALSE | L13: FALSE | M13: FALSE | N13: FALSE
A14: 9 | B14: 案件009 | I14: FALSE | J14: FALSE | K14: FALSE | L14: FALSE | M14: FALSE | N14: FALSE
A15: 10 | B15: 案件010 | I15: FALSE | J15: FALSE | K15: FALSE | L15: FALSE | M15: FALSE | N15: FALSE
A16: 11 | B16: 案件011 | I16: FALSE | J16: FALSE | K16: FALSE | L16: FALSE | M16: FALSE | N16: FALSE
A17: 12 | B17: 案件012 | I17: FALSE | J17: FALSE | K17: FALSE | L17: FALSE | M17: FALSE | N17: FALSE
... A105: 100 | B105: 案件100 | I105: FALSE | J105: FALSE | K105: FALSE | L105: FALSE | M105: FALSE | N105: FALSE

Sheet KPI・リスク管理
A1: KPI・リスク管理 ／ 10月完全移行ダッシュボード
A2: KPIは「案件進捗管理」シート（6行目～105行目）から自動集計されます。週次の実績（累計件数・稼働時間）と運用体制の確保人数のみ手入力してください。
A3: ※「計画累計引き継ぎ件数」「計画稼働時間」「想定人数4名」は現時点の計画値・試算値であり、確定実績ではありません。
A5: ① KPIサマリー（自動集計 ／ 集計元：案件進捗管理シート）
B6: 総案件数 | G6: 引き継ぎ完了件数 | L6: 引き継ぎ率 | Q6: 未引き継ぎ件数
B7: =COUNTA('案件進捗管理'!$B$6:$B$105) | G7: =SUMPRODUCT(('案件進捗管理'!$C$6:$C$105<>"")*(('案件進捗管理'!$I$6:$I$105=TRUE)+('案件進捗管理'!$I$6:$I$105="TRUE")>0)*(('案件進捗管理'!$J$6:$J$105=TRUE)+('案件進捗管理'!$J$6:$J$105="TRUE")>0)*(('案件進捗管理'!$K$6:$K$105=TRUE)+('案件進捗管理'!$K$6:$K$105="TRUE")>0)*(('案件進捗管理'!$L$6:$L$105=TRUE)+('案件進捗管理'!$L$6:$L$105="TRUE")>0)*(('案件進捗管理'!$M$6:$M$105=TRUE)+('案件進捗管理'!$M$6:$M$105="TRUE")>0)*(('案件進捗管理'!$N$6:$N$105=TRUE)+('案件進捗管理'!$N$6:$N$105="TRUE")>0)) | L7: =IFERROR(SUMPRODUCT(('案件進捗管理'!$C$6:$C$105<>"")*(('案件進捗管理'!$I$6:$I$105=TRUE)+('案件進捗管理'!$I$6:$I$105="TRUE")>0)*(('案件進捗管理'!$J$6:$J$105=TRUE)+('案件進捗管理'!$J$6:$J$105="TRUE")>0)*(('案件進捗管理'!$K$6:$K$105=TRUE)+('案件進捗管理'!$K$6:$K$105="TRUE")>0)*(('案件進捗管理'!$L$6:$L$105=TRUE)+('案件進捗管理'!$L$6:$L$105="TRUE")>0)*(('案件進捗管理'!$M$6:$M$105=TRUE)+('案件進捗管理'!$M$6:$M$105="TRUE")>0)*(('案件進捗管理'!$N$6:$N$105=TRUE)+('案件進捗管理'!$N$6:$N$105="TRUE")>0))/COUNTA('案件進捗管理'!$B$6:$B$105),0) | Q7: =COUNTA('案件進捗管理'!$B$6:$B$105)-SUMPRODUCT(('案件進捗管理'!$C$6:$C$105<>"")*(('案件進捗管理'!$I$6:$I$105=TRUE)+('案件進捗管理'!$I$6:$I$105="TRUE")>0)*(('案件進捗管理'!$J$6:$J$105=TRUE)+('案件進捗管理'!$J$6:$J$105="TRUE")>0)*(('案件進捗管理'!$K$6:$K$105=TRUE)+('案件進捗管理'!$K$6:$K$105="TRUE")>0)*(('案件進捗管理'!$L$6:$L$105=TRUE)+('案件進捗管理'!$L$6:$L$105="TRUE")>0)*(('案件進捗管理'!$M$6:$M$105=TRUE)+('案件進捗管理'!$M$6:$M$105="TRUE")>0)*(('案件進捗管理'!$N$6:$N$105=TRUE)+('案件進捗管理'!$N$6:$N$105="TRUE")>0))
B8: 移行対象の全案件数 | G8: 8項目すべて充足＋担当者確定の案件 | L8: 引き継ぎ完了件数 ÷ 総案件数 | Q8: 9/27までにゼロにする
B10: 単独運用可能件数 | G10: 単独運用率 | L10: 要確認案件数 | Q10: 遅延案件数
B11: =COUNTIF('案件進捗管理'!$O$6:$O$105,"可") | G11: =IFERROR(COUNTIF('案件進捗管理'!$O$6:$O$105,"可")/COUNTA('案件進捗管理'!$B$6:$B$105),0) | L11: =COUNTA('案件進捗管理'!$Q$6:$Q$105) | Q11: =IF(TODAY()>DATE(2026,9,27),COUNTA('案件進捗管理'!$B$6:$B$105)-SUMPRODUCT(('案件進捗管理'!$C$6:$C$105<>"")*(('案件進捗管理'!$I$6:$I$105=TRUE)+('案件進捗管理'!$I$6:$I$105="TRUE")>0)*(('案件進捗管理'!$J$6:$J$105=TRUE)+('案件進捗管理'!$J$6:$J$105="TRUE")>0)*(('案件進捗管理'!$K$6:$K$105=TRUE)+('案件進捗管理'!$K$6:$K$105="TRUE")>0)*(('案件進捗管理'!$L$6:$L$105=TRUE)+('案件進捗管理'!$L$6:$L$105="TRUE")>0)*(('案件進捗管理'!$M$6:$M$105=TRUE)+('案件進捗管理'!$M$6:$M$105="TRUE")>0)*(('案件進捗管理'!$N$6:$N$105=TRUE)+('案件進捗管理'!$N$6:$N$105="TRUE")>0)),0)
B12: 単独運用可否＝「可」の件数 | G12: 単独運用可能件数 ÷ 総案件数 | L12: 「課題」欄に記載がある案件 | Q12: 9/27（引き継ぎ完了期限）超過時の未引き継ぎ件数
B14: 今週の実績稼働時間 | G14: 累計実績稼働時間 | L14: 1件あたり平均引き継ぎ工数 | Q14: 計画総工数（計画値）
B15: =IFERROR(INDEX($R$25:$R$30,MATCH(TODAY(),$D$25:$D$30,1)),0) | G15: =SUM($R$25:$R$30) | L15: =IF(SUMPRODUCT(('案件進捗管理'!$C$6:$C$105<>"")*(('案件進捗管理'!$I$6:$I$105=TRUE)+('案件進捗管理'!$I$6:$I$105="TRUE")>0)*(('案件進捗管理'!$J$6:$J$105=TRUE)+('案件進捗管理'!$J$6:$J$105="TRUE")>0)*(('案件進捗管理'!$K$6:$K$105=TRUE)+('案件進捗管理'!$K$6:$K$105="TRUE")>0)*(('案件進捗管理'!$L$6:$L$105=TRUE)+('案件進捗管理'!$L$6:$L$105="TRUE")>0)*(('案件進捗管理'!$M$6:$M$105=TRUE)+('案件進捗管理'!$M$6:$M$105="TRUE")>0)*(('案件進捗管理'!$N$6:$N$105=TRUE)+('案件進捗管理'!$N$6:$N$105="TRUE")>0))=0,0,SUM($R$25:$R$30)/SUMPRODUCT(('案件進捗管理'!$C$6:$C$105<>"")*(('案件進捗管理'!$I$6:$I$105=TRUE)+('案件進捗管理'!$I$6:$I$105="TRUE")>0)*(('案件進捗管理'!$J$6:$J$105=TRUE)+('案件進捗管理'!$J$6:$J$105="TRUE")>0)*(('案件進捗管理'!$K$6:$K$105=TRUE)+('案件進捗管理'!$K$6:$K$105="TRUE")>0)*(('案件進捗管理'!$L$6:$L$105=TRUE)+('案件進捗管理'!$L$6:$L$105="TRUE")>0)*(('案件進捗管理'!$M$6:$M$105=TRUE)+('案件進捗管理'!$M$6:$M$105="TRUE")>0)*(('案件進捗管理'!$N$6:$N$105=TRUE)+('案件進捗管理'!$N$6:$N$105="TRUE")>0))) | Q15: =SUM($P$25:$P$30)
B16: 本日が属する週の実績稼働時間 | G16: 週次実績の合計（手入力値） | L16: 累計実績稼働時間 ÷ 引き継ぎ完了件数 | Q16: 4名体制・1名あたり約120時間の試算値
A18: ② 10月完全移行 判定（管理ルールに基づく自動判定）
B19: ① 引き継ぎ完了判定 （基準日：2026/9/27） | K19: ② 運用体制 確保判定 （基準日：2026/8/30） | S19: 確保済み人数 【入力】
B20: =IF(SUMPRODUCT(('案件進捗管理'!$C$6:$C$105<>"")*(('案件進捗管理'!$I$6:$I$105=TRUE)+('案件進捗管理'!$I$6:$I$105="TRUE")>0)*(('案件進捗管理'!$J$6:$J$105=TRUE)+('案件進捗管理'!$J$6:$J$105="TRUE")>0)*(('案件進捗管理'!$K$6:$K$105=TRUE)+('案件進捗管理'!$K$6:$K$105="TRUE")>0)*(('案件進捗管理'!$L$6:$L$105=TRUE)+('案件進捗管理'!$L$6:$L$105="TRUE")>0)*(('案件進捗管理'!$M$6:$M$105=TRUE)+('案件進捗管理'!$M$6:$M$105="TRUE")>0)*(('案件進捗管理'!$N$6:$N$105=TRUE)+('案件進捗管理'!$N$6:$N$105="TRUE")>0))>=COUNTA('案件進捗管理'!$B$6:$B$105),"OK：100件の引き継ぎ完了 → 10月1日 完全移行 可能",IF(TODAY()>DATE(2026,9,27),"リスクあり：9/27時点で引き継ぎ未完了（残 "&(COUNTA('案件進捗管理'!$B$6:$B$105)-SUMPRODUCT(('案件進捗管理'!$C$6:$C$105<>"")*(('案件進捗管理'!$I$6:$I$105=TRUE)+('案件進捗管理'!$I$6:$I$105="TRUE")>0)*(('案件進捗管理'!$J$6:$J$105=TRUE)+('案件進捗管理'!$J$6:$J$105="TRUE")>0)*(('案件進捗管理'!$K$6:$K$105=TRUE)+('案件進捗管理'!$K$6:$K$105="TRUE")>0)*(('案件進捗管理'!$L$6:$L$105=TRUE)+('案件進捗管理'!$L$6:$L$105="TRUE")>0)*(('案件進捗管理'!$M$6:$M$105=TRUE)+('案件進捗管理'!$M$6:$M$105="TRUE")>0)*(('案件進捗管理'!$N$6:$N$105=TRUE)+('案件進捗管理'!$N$6:$N$105="TRUE")>0)))&" 件）","計画進行中：残 "&(COUNTA('案件進捗管理'!$B$6:$B$105)-SUMPRODUCT(('案件進捗管理'!$C$6:$C$105<>"")*(('案件進捗管理'!$I$6:$I$105=TRUE)+('案件進捗管理'!$I$6:$I$105="TRUE")>0)*(('案件進捗管理'!$J$6:$J$105=TRUE)+('案件進捗管理'!$J$6:$J$105="TRUE")>0)*(('案件進捗管理'!$K$6:$K$105=TRUE)+('案件進捗管理'!$K$6:$K$105="TRUE")>0)*(('案件進捗管理'!$L$6:$L$105=TRUE)+('案件進捗管理'!$L$6:$L$105="TRUE")>0)*(('案件進捗管理'!$M$6:$M$105=TRUE)+('案件進捗管理'!$M$6:$M$105="TRUE")>0)*(('案件進捗管理'!$N$6:$N$105=TRUE)+('案件進捗管理'!$N$6:$N$105="TRUE")>0)))&" 件（完了期限 2026/9/27）")) | K20: =IF($S$20>=3,"OK：運用体制 確保済み（"&$S$20&"名）",IF(TODAY()>DATE(2026,8,30),"要再計画：8/30時点で3～4名の体制が未確保","体制確保 調整中（目標4名・現在 "&$S$20&"名）")) | S20: 0
A23: ③ 週次 計画／実績 管理（薄い黄色セルのみ手入力）
B24: 週 | D24: 期間開始日 （計画） | F24: 期間終了日 （計画） | H24: 計画累計 引き継ぎ件数 | J24: 計画進捗率 | L24: 実績累計 引き継ぎ件数 【入力】 | N24: 実績進捗率 | P24: 計画稼働時間 （計画値） | R24: 実績稼働時間 【入力】 | T24: 差異 (実績-計画)
B25: 第1週 | D25: 46258 | F25: 46264 | H25: 10 | J25: =H25/$B$7 | N25: =IF(L25="","",L25/$B$7) | P25: 60 | T25: =IF(R25="","",R25-P25)
B26: 第2週 | D26: 46265 | F26: 46271 | H26: 30 | J26: =H26/$B$7 | N26: =IF(L26="","",L26/$B$7) | P26: 90 | T26: =IF(R26="","",R26-P26)
B27: 第3週 | D27: 46272 | F27: 46278 | H27: 55 | J27: =H27/$B$7 | N27: =IF(L27="","",L27/$B$7) | P27: 100 | T27: =IF(R27="","",R27-P27)
B28: 第4週 | D28: 46279 | F28: 46285 | H28: 80 | J28: =H28/$B$7 | N28: =IF(L28="","",L28/$B$7) | P28: 100 | T28: =IF(R28="","",R28-P28)
B29: 第5週 | D29: 46286 | F29: 46292 | H29: 100 | J29: =H29/$B$7 | N29: =IF(L29="","",L29/$B$7) | P29: 80 | T29: =IF(R29="","",R29-P29)
B30: 第6週 | D30: 46293 | F30: 46295 | H30: 100 | J30: =H30/$B$7 | N30: =IF(L30="","",L30/$B$7) | P30: 50 | T30: =IF(R30="","",R30-P30)
B31: 合計 / 最終 | H31: =MAX(H25:H30) | J31: =H31/$B$7 | L31: =IF(COUNT(L25:L30)=0,"",MAX(L25:L30)) | N31: =IF(L31="","",L31/$B$7) | P31: =SUM(P25:P30) | R31: =SUM(R25:R30) | T31: =R31-P31
A33: ④ 計画進捗率 vs 実績進捗率（実績は上表の「実績累計引き継ぎ件数」を入力すると反映されます）
A54: ⑤ リスク管理（初期登録済み ／ 対応状況は手入力）
B55: No. | C55: リスク | F55: 影響 | I55: 対応（対策） | M55: 発生可能性 | O55: 影響度 | Q55: 対応期限 | S55: 対応状況
B56: 1 | C56: 8月中に必要人数を確保できない | F56: 10月100件完全移行が困難になる | I56: アサイン状況を最優先で確認し、必要に応じて複数名体制へ変更 | M56: 高 | O56: 大 | Q56: 46264 | S56: 未対応
B57: 2 | C57: 1案件あたりの実工数が想定を上回る | F57: 週間引き継ぎ件数未達 | I57: 初期10～30案件の実績から平均工数を再計算し、計画を修正 | M57: 中 | O57: 大 | Q57: 46271 | S57: 未対応
B58: 3 | C58: 顧客ごとの例外運用が多い | F58: 担当者の習熟に時間がかかる | I58: 案件をA・B・Cで難易度分類し、C案件を早めに洗い出す | M58: 高 | O58: 中 | Q58: 46264 | S58: 未対応
B59: 4 | C59: Word版チェックリストのExcel移行が遅れる | F59: 引き継ぎ効率低下 | I59: 引き継ぎ対象案件を優先してExcel化 | M59: 中 | O59: 中 | Q59: 46285 | S59: 未対応
B60: 5 | C60: ID、PW、各システム権限が不足 | F60: 実案件を担当できない | I60: 9月前半までではなく、引き継ぎ開始時点で必要権限を確認 | M60: 高 | O60: 大 | Q60: 46278 | S60: 未対応
B61: 6 | C61: 9月末に未引き継ぎ案件が残る | F61: 10月完全移行不可 | I61: 9月21日～27日までに100件引き継ぎ完了を必須条件とし、9月28日～30日はバッファ期間とする | M61: 中 | O61: 大 | Q61: 46292 | S61: 未対応
A63: ⑥ 重要な管理ルール（社内・クライアント共通の合意事項）
A64: 【「引き継ぎ完了」の定義】 単に業務説明を受けた状態は「引き継ぎ完了」ではありません。以下すべてを確認できた案件のみを「引き継ぎ完了」とします。 ①業務内容理解 ②勤怠情報取得可能 ③給与計算可能 ④チェックリスト更新可能 ⑤顧客対応方法理解 ⑥納品方法理解 ⑦進捗管理更新可能 ⑧担当者確定
A65: 【判定ルール①】2026年9月27日時点で100件の引き継ぎが完了していない場合、10月1日の完全移行に対して「リスクあり」と判定します（上部②に自動表示）。
A66: 【判定ルール②】2026年8月30日時点で必要な3～4名程度の運用体制が確保できていない場合、10月完全移行について「要再計画」と表示します（上部②に自動表示）。
A67: 【スケジュールの考え方】9月末に引き継ぎを開始するのではなく、9月第4週（～9/27）までに100案件の引き継ぎを完了させ、9月28日～30日は新規引き継ぎを行わず、修正・確認・リハーサルのバッファ期間として使用します。
A68: 【計画値の取り扱い】想定総工数480時間／1名あたり約120時間／週20～25時間稼働／4名体制／週間引き継ぎ件数は、いずれも現時点の計画値・試算値です。確定実績ではないため、初期10～30案件の実績が出た段階で平均工数を再計算し、計画を見直してください。
...
